Workbook

Sheet Diccionario
A1: Canal SCJ | B1: Canal NIQ | D1: Homologación | E1: Segmento SCJ | F1: Segmento NIQ
A2: Supermercado | B2: Supermercados | D2: Repelente | E2: Mosquito + Repelente Gel, crema, spray y aerosol | F2: PERSONAL REPELLENT + MOSQUITO
A3: Distribuidor, Mayorista | B3: Tradicional | D3: Insecticida | E3: Mosquito + MMM Aero | F3: FLYING INSECT KILLER + Todos los segmentos
A4: eCommerce | B4: No cubierto | D4: Pesticidas | E4: Todo + Toda la categoria menos repelentes y MMM Aero | F4: Todas las categorias menos PERSONAL REPELLENT y FLYING INSECT KILLER + Todos los segmentos

Sheet Dinamica S.
A1: Canal | B1: (Todas)
A2: Sub Negocio | B2: (Todas)
A3: Sub Categoría | B3: (Todas)
A5: Etiquetas de fila | B5: Suma de jul-22 | C5: Suma de ago-22 | D5: Suma de sep-22 | E5: Suma de oct-22 | F5: Suma de nov-22 | G5: Suma de dic-22 | H5: Suma de ene-23 | I5: Suma de feb-23 | J5: Suma de mar-23 | K5: Suma de abr-23 | L5: Suma de may-23 | M5: Suma de jun-23 | N5: Suma de jul-23 | O5: Suma de ago-23 | P5: Suma de sep-23 | Q5: Suma de oct-23 | R5: Suma de nov-23 | S5: Suma de dic-23 | T5: Suma de ene-24 | U5: Suma de feb-24 | V5: Suma de mar-24 | W5: Suma de abr-24 | X5: Suma de may-24 | Y5: Suma de jun-24 | Z5: Suma de jul-24 | AA5: Suma de ago-24 | AB5: Suma de sep-24
A6: Bayg | B6: 280 | C6: 2786 | D6: 10864 | E6: 9009 | F6: 9216 | G6: 5301 | H6: 1432 | I6: 1586 | J6: 1791 | K6: 1195 | L6: 1087 | M6: 367 | N6: 291 | O6: 1186 | P6: 8801 | Q6: 12095 | R6: 6606 | S6: 3074 | T6: 2581 | U6: 2660 | V6: 1908 | W6: 2132 | X6: 1672 | Y6: 270 | Z6: 283 | AA6: 370 | AB6: 8444
A7: Fuyi | B7: 79 | C7: 345 | D7: 10504 | E7: 14510 | F7: 12887 | G7: 10144 | H7: 3895 | I7: 2693 | J7: 2786 | K7: 1578 | L7: 1071 | M7: 596 | N7: 233 | O7: 316 | P7: 7083 | Q7: 11713 | R7: 11628 | S7: 9079 | T7: 9549 | U7: 5228 | V7: 5670 | W7: 6545 | X7: 1997 | Y7: 602 | Z7: 378 | AA7: 774 | AB7: 11157
A8: Off! | B8: 293 | C8: 120 | D8: 4216 | E8: 5155 | F8: 5341 | G8: 5270 | H8: 4327 | I8: 1831 | J8: 1250 | K8: 497 | L8: 503 | M8: 77 | N8: 42 | O8: 109 | P8: 3072 | Q8: 5944 | R8: 6595 | S8: 7909 | T8: 19478 | U8: 9535 | V8: 9915 | W8: 13079 | X8: 2633 | Y8: 1058 | Z8: 522 | AA8: 3423 | AB8: 6328
A9: Raid | B9: 3254 | C9: 2796 | D9: 45987 | E9: 37318 | F9: 36378 | G9: 23554 | H9: 13351 | I9: 10482 | J9: 10467 | K9: 7131 | L9: 5852 | M9: 2493 | N9: 1681 | O9: 4821 | P9: 30592 | Q9: 35523 | R9: 30291 | S9: 23486 | T9: 21994 | U9: 14945 | V9: 13578 | W9: 13494 | X9: 4897 | Y9: 1535 | Z9: 1829 | AA9: 1279 | AB9: 32920
A10: Total general | B10: 3906 | C10: 6047 | D10: 71571 | E10: 65992 | F10: 63822 | G10: 44269 | H10: 23005 | I10: 16592 | J10: 16294 | K10: 10401 | L10: 8513 | M10: 3533 | N10: 2247 | O10: 6432 | P10: 49548 | Q10: 65275 | R10: 55120 | S10: 43548 | T10: 53602 | U10: 32368 | V10: 31071 | W10: 35250 | X10: 11199 | Y10: 3465 | Z10: 3012 | AA10: 5846 | AB10: 58849
A12: Sub Negocio | B12: (Todas)
A13: Sub Categoría | B13: (Varios elementos)
A15: Canal | B15: Marca | C15: Suma de jul-22 | D15: Suma de ago-22 | E15: Suma de sep-22 | F15: Suma de oct-22 | G15: Suma de nov-22 | H15: Suma de dic-22 | I15: Suma de ene-23 | J15: Suma de feb-23 | K15: Suma de mar-23 | L15: Suma de abr-23 | M15: Suma de may-23 | N15: Suma de jun-23 | O15: Suma de jul-23 | P15: Suma de ago-23 | Q15: Suma de sep-23 | R15: Suma de oct-23 | S15: Suma de nov-23 | T15: Suma de dic-23 | U15: Suma de ene-24 | V15: Suma de feb-24 | W15: Suma de mar-24 | X15: Suma de abr-24 | Y15: Suma de may-24 | Z15: Suma de jun-24 | AA15: Suma de jul-24 | AB15: Suma de ago-24 | AC15: Suma de sep-24
A16: Ecommerce | B16: Baygon | C16: 0 | D16: 0 | E16: 0 | F16: 0 | G16: 0 | H16: 0 | I16: 0 | J16: 0 | K16: 0 | L16: 0 | M16: 0 | N16: 0 | O16: 0 | P16: 0 | Q16: 0 | R16: 0 | S16: 0 | T16: 372 | U16: 0 | V16: 240 | W16: 0 | X16: 0 | Y16: 0 | Z16: 0 | AA16: 0 | AB16: 0 | AC16: 0
B17: Fuyi | C17: 0 | D17: 0 | E17: 0 | F17: 0 | G17: 0 | H17: 0 | I17: 0 | J17: 0 | K17: 0 | L17: 0 | M17: 0 | N17: 0 | O17: 0 | P17: 0 | Q17: 0 | R17: 0 | S17: 0 | T17: 0 | U17: 0 | V17: 160 | W17: 880 | X17: 0 | Y17: 80 | Z17: 0 | AA17: 100 | AB17: 0 | AC17: 0
B18: Raid | C18: 0 | D18: 0 | E18: 0 | F18: 0 | G18: 0 | H18: 0 | I18: 0 | J18: 0 | K18: 0 | L18: 0 | M18: 0 | N18: 0 | O18: 0 | P18: 0 | Q18: 0 | R18: 30 | S18: 216 | T18: 954 | U18: 510 | V18: 822 | W18: 168 | X18: 796 | Y18: 84 | Z18: 12 | AA18: 232 | AB18: 12 | AC18: 168
A19: Total general | C19: 0 | D19: 0 | E19: 0 | F19: 0 | G19: 0 | H19: 0 | I19: 0 | J19: 0 | K19: 0 | L19: 0 | M19: 0 | N19: 0 | O19: 0 | P19: 0 | Q19: 0 | R19: 30 | S19: 216 | T19: 1326 | U19: 510 | V19: 1222 | W19: 1048 | X19: 796 | Y19: 164 | Z19: 12 | AA19: 332 | AB19: 12 | AC19: 168
AH27: Var. UAM YTD
C28: 44743 | D28: 44774 | E28: 44805 | F28: 44835 | G28: 44866 | H28: 44896 | I28: 44927 | J28: 44958 | K28: 44986 | L28: 45017 | M28: 45047 | N28: 45078 | O28: 45108 | P28: 45139 | Q28: 45170 | R28: 45200 | S28: 45231 | T28: 45261 | U28: 45292 | V28: 45323 | W28: 45352 | X28: 45383 | Y28: 45413 | Z28: 45444 | AA28: 45474 | AB28: 45505 | AC28: 45536 | AE28: UAM-1 YTD | AF28: UAM YTD | AH28: NIQ | AI28: SCJ
B29: NIQ | C29: 13235.664 | D29: 11397.39 | E29: 11858.228 | F29: 12763.397 | G29: 24300.67 | H29: 47010.163 | I29: 63846.878 | J29: 55757.033 | K29: 60897.754 | L29: 41521.456 | M29: 31693.38 | N29: 21258.457 | O29: 17629.917 | P29: 14074.227 | Q29: 14222.574 | R29: 20753.826 | S29: 31587.913 | T29: 58557.789 | U29: 109100.49 | V29: 102934.27 | W29: 139768.18 | X29: 160230.44 | Y29: 86562.917 | Z29: 41218.412 | AA29: 27728.966 | AB29: 18311.226 | AC29: 13719.402 | AE29: =+SUM(I29:Q29) -> 320901.68 | AF29: =+SUM(U29:AC29) -> 699574.3 | AH29: =+AF29/AE29-1 -> 1.180027 | AI29: =+AF30/AE30-1 -> 5.6710077
B30: SCJ | C30: 3480 | D30: 792 | E30: 33312 | F30: 63072 | G30: 53508 | H30: 53472 | I30: 41484 | J30: 11544 | K30: 8616 | L30: 3276 | M30: 444 | N30: 72 | O30: 12 | P30: 372 | Q30: 29088 | R30: 68004 | S30: 63384 | T30: 74868 | U30: 196512 | V30: 92496 | W30: 75432 | X30: 119688 | Y30: 25032 | Z30: 7956 | AA30: 2448 | AB30: 46944 | AC30: 66624 | AE30: =+SUM(I30:Q30) -> 94908 | AF30: =+SUM(U30:AC30) -> 633132
U31: =+SUM(M29:U29)/SUM(M30:U30)*100 -> 73.685536 | V31: =+SUM(N29:V29)/SUM(N30:V30)*100 -> 74.335655 | W31: =+SUM(O29:W29)/SUM(O30:W30)*100 -> 84.747801 | X31: =+SUM(P29:X29)/SUM(P30:X30)*100 -> 90.468172 | Y31: =+SUM(Q29:Y29)/SUM(Q30:Y30)*100 -> 97.208128 | Z31: =+SUM(R29:Z29)/SUM(R30:Z30)*100 -> 103.77983 | AA31: =+SUM(S29:AA29)/SUM(S30:AA30)*100 -> 115.18257 | AB31: =+SUM(T29:AB29)/SUM(T30:AB30)*100 -> 116.06494 | AC31: =+SUM(U29:AC29)/SUM(U30:AC30)*100 -> 110.49423
AE33: =+SUM(D30:J30) -> 257184 | AF33: =+AE34/AE33*100 -> 126.3793
AE34: =+SUM(G29:M29) -> 325027.33

Sheet Shipments
A1: Category | B1: Segment | C1: Country | D1: Channel Name | E1: Brand | F1: SKU | G1: Facts | H1: 44743 | I1: 44774 | J1: 44805 | K1: 44835 | L1: 44866 | M1: 44896 | N1: 44927 | O1: 44958 | P1: 44986 | Q1: 45017 | R1: 45047 | S1: 45078 | T1: 45108 | U1: 45139 | V1: 45170 | W1: 45200 | X1: 45231 | Y1: 45261 | Z1: 45292 | AA1: 45323 | AB1: 45352 | AC1: 45383 | AD1: 45413 | AE1: 45444 | AF1: 45474 | AG1: 45505 | AH1: 45536
A2: Espirales | B2: Pest Control | C2: Uruguay | D2: Distribuidor | E2: Raid | F2: Raid Espirales Lavanda | G2: Sales | H2: 0 | I2: 24 | J2: 3456 | K2: 1488 | L2: 4152 | M2: 6072 | N2: 3504 | O2: 2064 | P2: 2712 | Q2: 960 | R2: 0 | S2: 0 | T2: 0 | U2: 408 | V2: 3312 | W2: 6984 | X2: 4440 | Y2: 5304 | Z2: 7032 | AA2: 4416 | AB2: 2592 | AC2: 1560 | AD2: 0 | AE2: 0 | AF2: 168 | AG2: 72 | AH2: 7488
A3: Espirales | B3: Pest Control | C3: Uruguay | D3: Distribuidor | E3: Raid | F3: Raid Espirales Original | G3: Sales | H3: 0 | I3: 24 | J3: 3216 | K3: 2328 | L3: 4032 | M3: 5832 | N3: 2520 | O3: 1488 | P3: 2040 | Q3: 600 | R3: 312 | S3: 48 | T3: 72 | U3: 0 | V3: 2928 | W3: 6144 | X3: 3528 | Y3: 4872 | Z3: 6696 | AA3: 2232 | AB3: 1920 | AC3: 1320 | AD3: 3168 | AE3: 360 | AF3: 48 | AG3: 48 | AH3: 6384
A4: Espirales | B4: Pest Control | C4: Uruguay | D4: Distribuidor | E4: Raid | F4: Raid Espirales Sobres | G4: Sales | H4: 0 | I4: 0 | J4: 240 | K4: 336 | L4: 672 | M4: 360 | N4: 120 | O4: 96 | P4: 192 | Q4: 24 | R4: 0 | S4: 0 | T4: 0 | U4: 0 | V4: 120 | W4: 192 | X4: 240 | Y4: 0 | Z4: 456 | AA4: 1536 | AB4: 120 | AC4: 840 | AD4: 0 | AE4: 0 | AF4: 0 | AG4: 0 | AH4: 0
A5: Liquido Electrico | B5: Pest Control | C5: Uruguay | D5: Distribuidor | E5: Fuyi | F5: Fuyi 45N Ap. | G5: Sales | H5: 0 | I5: 0 | J5: 216 | K5: 288 | L5: 216 | M5: 306 | N5: 96 | O5: 60 | P5: 42 | Q5: 42 | R5: 36 | S5: 0 | T5: 0 | U5: 0 | V5: 288 | W5: 1080 | X5: 0 | Y5: 294 | Z5: 594 | AA5: 42 | AB5: 30 | AC5: 36 | AD5: 24 | AE5: 0 | AF5: 0 | AG5: 0 | AH5: 606
A6: Liquido Electrico | B6: Pest Control | C6: Uruguay | D6: Distribuidor | E6: Fuyi | F6: Fuyi 45N Rep. | G6: Sales | H6: 0 | I6: 12 | J6: 312 | K6: 732 | L6: 888 | M6: 588 | N6: 144 | O6: 216 | P6: 120 | Q6: 228 | R6: 168 | S6: 216 | T6: 0 | U6: 60 | V6: 552 | W6: 2052 | X6: 1284 | Y6: 660 | Z6: 1188 | AA6: 468 | AB6: 672 | AC6: 684 | AD6: 96 | AE6: 0 | AF6: 0 | AG6: 36 | AH6: 684
A7: Liquido Electrico | B7: Pest Control | C7: Uruguay | D7: Distribuidor | E7: Raid | F7: Raid 45N Ap. | G7: Sales | H7: 0 | I7: 60 | J7: 324 | K7: 60 | L7: 0 | M7: 0 | N7: 294 | O7: 102 | P7: 0 | Q7: 12 | R7: 72 | S7: 78 | T7: 0 | U7: 24 | V7: 264 | W7: 330 | X7: 60 | Y7: 504 | Z7: 2652 | AA7: 888 | AB7: 192 | AC7: 726 | AD7: 120 | AE7: 12 | AF7: 0 | AG7: 0 | AH7: 150
A8: Liquido Electrico | B8: Pest Control | C8: Uruguay | D8: Distribuidor | E8: Raid | F8: Raid 45N Rep. | G8: Sales | H8: 0 | I8: 60 | J8: 588 | K8: 2676 | L8: 3072 | M8: 1488 | N8: 1632 | O8: 636 | P8: 1164 | Q8: 468 | R8: 300 | S8: 312 | T8: 156 | U8: 264 | V8: 1764 | W8: 3840 | X8: 1956 | Y8: 1536 | Z8: 2568 | AA8: 1464 | AB8: 1128 | AC8: 2100 | AD8: 348 | AE8: 36 | AF8: 0 | AG8: 84 | AH8: 3720
A9: Liquido Electrico | B9: Pest Control | C9: Uruguay | D9: Distribuidor | E9: Raid | F9: Raid 45N Ap. Promo | G9: Sales | H9: 0 | I9: 0 | J9: 1380 | K9: 4104 | L9: 2742 | M9: 1962 | N9: 1308 | O9: 1182 | P9: 552 | Q9: 102 | R9: 18 | S9: 12 | T9: 0 | U9: 102 | V9: 2766 | W9: 3870 | X9: 2544 | Y9: 2910 | Z9: 0 | AA9: 0 | AB9: 0 | AC9: 0 | AD9: 0 | AE9: 0 | AF9: 0 | AG9: 0 | AH9: 2142
A10: Liquido Electrico | B10: Pest Control | C10: Uruguay | D10: Distribuidor | E10: Raid | F10: Raid 45N Rep. Bloosoms | G10: Sales | H10: 0 | I10: 0 | J10: 0 | K10: 0 | L10: 0 | M10: 0 | N10: 0 | O10: 0 | P10: 0 | Q10: 0 | R10: 0 | S10: 0 | T10: 0 | U10: 0 | V10: 480 | W10: 660 | X10: 360 | Y10: 540 | Z10: 288 | AA10: 240 | AB10: 0 | AC10: 360 | AD10: 0 | AE10: 0 | AF10: 0 | AG10: 0 | AH10: 444
A11: Liquido Electrico | B11: Pest Control | C11: Uruguay | D11: Distribuidor | E11: Fuyi | F11: Fuyi 45 Noches Rep. | G11: Sales | H11: 0 | I11: 0 | J11: 0 | K11: 0 | L11: 0 | M11: 0 | N11: 0 | O11: 0 | P11: 0 | Q11: 0 | R11: 0 | S11: 0 | T11: 0 | U11: 0 | V11: 0 | W11: 0 | X11: 0 | Y11: 0 | Z11: 0 | AA11: 0 | AB11: 0 | AC11: 0 | AD11: 0 | AE11: 0 | AF11: 0 | AG11: 0 | AH11: 552
A12: Tabletas | B12: Pest Control | C12: Uruguay | D12: Distribuidor | E12: Fuyi | F12: Fuyi Tabletas Rep. x12 | G12: Sales | H12: 0 | I12: 60 | J12: 2160 | K12: 3440 | L12: 6780 | M12: 4120 | N12: 1260 | O12: 1520 | P12: 1500 | Q12: 900 | R12: 840 | S12: 160 | T12: 200 | U12: 120 | V12: 3160 | W12: 11300 | X12: 7120 | Y12: 6120 | Z12: 4800 | AA12: 3640 | AB12: 1900 | AC12: 3100 | AD12: 560 | AE12: 360 | AF12: 80 | AG12: 100 | AH12: 7160
... A206: Polillas Continuos | B206: Pest Control | C206: Uruguay | D206: Supermercados | E206: Raid | F206: Raid Antipolillas Continuo | G206: Sales | H206: 144 | I206: 180 | J206: 1428 | K206: 564 | L206: 252 | M206: 552 | N206: 504 | O206: 192 | P206: 684 | Q206: 432 | R206: 576 | S206: 132 | T206: 168 | U206: 0 | V206: 0 | W206: 0 | X206: 0 | Y206: 0 | Z206: 0 | AA206: 0 | AB206: 0 | AC206: 0 | AD206: 0 | AE206: 0 | AF206: 0 | AG206: 0 | AH206: 0

Sheet Dinamica D.
A1: Facts | B1: Units
A2: CATEGORY | B2: (Varios elementos)
A3: SEGMENT | B3: (Todas)
A4: FORM | B4: (Todas)
A6: Markets | B6: BRAND | C6: Suma de Sep 21 - w/e 22/09/21 | D6: Suma de Oct 21 - w/e 23/10/21 | E6: Suma de Nov 21 - w/e 22/11/21 | F6: Suma de Dec 21 - w/e 23/12/21 | G6: Suma de Jan 22 - w/e 23/01/22 | H6: Suma de Feb 22 - w/e 20/02/22 | I6: Suma de Mar 22 - w/e 23/03/22 | J6: Suma de Apr 22 - w/e 22/04/22 | K6: Suma de May 22 - w/e 23/05/22 | L6: Suma de Jun 22 - w/e 22/06/22 | M6: Suma de Jul 22 - w/e 23/07/22 | N6: Suma de Aug 22 - w/e 23/08/22 | O6: Suma de Sep 22 - w/e 22/09/22 | P6: Suma de Oct 22 - w/e 23/10/22 | Q6: Suma de Nov 22 - w/e 22/11/22 | R6: Suma de Dec 22 - w/e 23/12/22 | S6: Suma de Jan 23 - w/e 23/01/23 | T6: Suma de Feb 23 - w/e 20/02/23 | U6: Suma de Mar 23 - w/e 23/03/23 | V6: Suma de Apr 23 - w/e 22/04/23 | W6: Suma de May 23 - w/e 23/05/23 | X6: Suma de Jun 23 - w/e 22/06/23 | Y6: Suma de Jul 23 - w/e 23/07/23 | Z6: Suma de Aug 23 - w/e 23/08/23 | AA6: Suma de Sep 23 - w/e 22/09/23 | AB6: Suma de Oct 23 - w/e 23/10/23 | AC6: Suma de Nov 23 - w/e 22/11/23 | AD6: Suma de Dec 23 - w/e 23/12/23 | AE6: Suma de Jan 24 - w/e 23/01/24 | AF6: Suma de Feb 24 - w/e 21/02/24 | AG6: Suma de Mar 24 - w/e 23/03/24 | AH6: Suma de Apr 24 - w/e 22/04/24 | AI6: Suma de May 24 - w/e 23/05/24 | AJ6: Suma de Jun 24 - w/e 22/06/24 | AK6: Suma de Jul 24 - w/e 23/07/24 | AL6: Suma de Aug 24 - w/e 23/08/24 | AM6: Suma de Sep 24 - w/e 22/09/24
A7: T.URUGUAY AUTOSERVICIOS | B7: RAID | C7: 9669.915 | D7: 15195.329 | E7: 20601.978 | F7: 26857.238 | G7: 37377.669 | H7: 37062.562 | I7: 28260.304 | J7: 21930.171 | K7: 15108.236 | L7: 10613.238 | M7: 8672.063 | N7: 8103.106 | O7: 8685.099 | P7: 12288.99 | Q7: 21386.925 | R7: 28025.976 | S7: 32749.309 | T7: 29094.92 | U7: 27289.186 | V7: 22123.327 | W7: 19230.477 | X7: 13985.487 | Y7: 11251.014 | Z7: 7138.242 | AA7: 8184.036 | AB7: 13084.507 | AC7: 19564.539 | AD7: 30895.205 | AE7: 39607.318 | AF7: 40205.941 | AG7: 48043.949 | AH7: 44727.109 | AI7: 30578.515 | AJ7: 23120.884 | AK7: 15701.495 | AL7: 11025.06 | AM7: 8858.764
A8: T.URUGUAY INC | B8: RAID | C8: 1788.378 | D8: 3166.816 | E8: 5261.877 | F8: 7232.076 | G8: 11815.762 | H8: 10040.748 | I8: 8200.421 | J8: 5260.241 | K8: 3076.23 | L8: 1554.901 | M8: 1517.197 | N8: 1458.899 | O8: 1594.405 | P8: 2520.332 | Q8: 5338.954 | R8: 9034.459 | S8: 9003.629 | T8: 8636.579 | U8: 8937.868 | V8: 6025.001 | W8: 4406.906 | X8: 3094.726 | Y8: 2823.688 | Z8: 1979.436 | AA8: 2354.141 | AB8: 3325.12 | AC8: 4352.154 | AD8: 9060.484 | AE8: 13168.806 | AF8: 10741.545 | AG8: 14214.599 | AH8: 13637.519 | AI8: 9878.99 | AJ8: 5731.376 | AK8: 4470.742 | AL8: 3547.387 | AM8: 2659.849
A9: T.URUGUAY KIOSCOS+MINIMERCADOS | B9: RAID | C9: 2568.256 | D9: 2371.154 | E9: 4104.762 | F9: 5913.32 | G9: 9821.264 | H9: 7999.773 | I9: 7409.021 | J9: 5443.361 | K9: 3771.908 | L9: 2868.324 | M9: 2322.494 | N9: 2968.706 | O9: 2617.322 | P9: 3186.575 | Q9: 3532.86 | R9: 5012.778 | S9: 4694.196 | T9: 4951.428 | U9: 6282.915 | V9: 4869.734 | W9: 3073.038 | X9: 1913.386 | Y9: 1540.681 | Z9: 2282.15 | AA9: 1982.619 | AB9: 2513.066 | AC9: 2844.681 | AD9: 4027.364 | AE9: 5363.512 | AF9: 5527.338 | AG9: 7694.767 | AH9: 7204.383 | AI9: 5855.797 | AJ9: 4475.187 | AK9: 3076.691 | AL9: 1906.65 | AM9: 1785.764
A10: T.URUGUAY TRADICIONALES | B10: RAID | C10: 7655.676 | D10: 8142.304 | E10: 10326.75 | F10: 15100.829 | G10: 17734.834 | H10: 15298.945 | I10: 14261.876 | J10: 13667.106 | K10: 10862.082 | L10: 7205.207 | M10: 6104.765 | N10: 6774.083 | O10: 6604.501 | P10: 7091.266 | Q10: 10547.81 | R10: 13117.394 | S10: 18168.19 | T10: 19176.798 | U10: 22329.606 | V10: 16052.508 | W10: 13413.158 | X10: 9380.835 | Y10: 9302.002 | Z10: 8305.453 | AA10: 10202.951 | AB10: 10947.946 | AC10: 13845.445 | AD10: 17068.57 | AE10: 21812.208 | AF10: 22614.415 | AG10: 28538.784 | AH10: 28076.507 | AI10: 20130.658 | AJ10: 16094.049 | AK10: 12793.619 | AL10: 9474.299 | AM10: 7470.761
A11: Total general | C11: 21682.225 | D11: 28875.603 | E11: 40295.367 | F11: 55103.463 | G11: 76749.529 | H11: 70402.028 | I11: 58131.622 | J11: 46300.879 | K11: 32818.456 | L11: 22241.67 | M11: 18616.519 | N11: 19304.794 | O11: 19501.327 | P11: 25087.163 | Q11: 40806.549 | R11: 55190.607 | S11: 64615.324 | T11: 61859.725 | U11: 64839.575 | V11: 49070.57 | W11: 40123.579 | X11: 28374.434 | Y11: 24917.385 | Z11: 19705.281 | AA11: 22723.747 | AB11: 29870.639 | AC11: 40606.819 | AD11: 61051.623 | AE11: 79951.844 | AF11: 79089.239 | AG11: 98492.099 | AH11: 93645.518 | AI11: 66443.96 | AJ11: 49421.496 | AK11: 36042.547 | AL11: 25953.396 | AM11: 20775.138
A20: Proporción Ventas
A22: Repelentes | B22: 44440 | C22: 44470 | D22: 44501 | E22: 44531 | F22: 44562 | G22: 44593 | H22: 44621 | I22: 44652 | J22: 44682 | K22: 44713 | L22: 44743 | M22: 44774 | N22: 44805 | O22: 44835 | P22: 44866 | Q22: 44896 | R22: 44927 | S22: 44958 | T22: 44986 | U22: 45017 | V22: 45047 | W22: 45078 | X22: 45108 | Y22: 45139 | Z22: 45170 | AA22: 45200 | AB22: 45231 | AC22: 45261 | AD22: 45292 | AE22: 45323 | AF22: 45352 | AG22: 45383 | AH22: 45413 | AI22: 45444 | AJ22: 45474 | AK22: 45505 | AL22: 45536
A23: FUYI | B23: 0.18793924 | C23: 0.40606034 | D23: 0.46592855 | E23: 0.76597461 | F23: 1.1037483 | G23: 1.3092284 | H23: 0.98375382 | I23: 0.57510285 | J23: 0.49976741 | K23: 0.35131781 | L23: 0.30823131 | M23: 0.23669268 | N23: 0.23278618 | O23: 0.36994816 | P23: 0.33570001 | Q23: 0.75334165 | R23: 0.90019827 | S23: 0.82175248 | T23: 1.015392 | U23: 0.49946183 | V23: 0.36822399 | W23: 0.28343933 | X23: 0.26766332 | Y23: 0.38395987 | Z23: 0.23544774 | AA23: 0.31841357 | AB23: 0.69509111 | AC23: 1.0218149 | AD23: 1.6392389 | AE23: 1.7661837 | AF23: 1.6172066 | AG23: 2.160342 | AH23: 1.4961001 | AI23: 0.53113164 | AJ23: 0.33747648 | AK23: 0.21345318 | AL23: 0.30557426
A24: OFF! | B24: =+C11/D.Inventario!B17 -> 0.40033695 | C24: =+D11/D.Inventario!C17 -> 0.57479956 | D24: =+E11/D.Inventario!D17 -> 0.70143938 | E24: =+F11/D.Inventario!E17 -> 0.91501802 | F24: =+G11/D.Inventario!F17 -> 1.3063272 | G24: =+H11/D.Inventario!G17 -> 1.1584502 | H24: =+I11/D.Inventario!H17 -> 0.99869896 | I24: =+J11/D.Inventario!I17 -> 0.85321982 | ... AL24: =+AM11/D.Inventario!AL17 -> 0.4818118
A36: Insecticida | B36: 44440 | C36: 44470 | D36: 44501 | E36: 44531 | F36: 44562 | G36: 44593 | H36: 44621 | I36: 44652 | J36: 44682 | K36: 44713 | L36: 44743 | M36: 44774 | N36: 44805 | O36: 44835 | P36: 44866 | Q36: 44896 | R36: 44927 | S36: 44958 | T36: 44986 | U36: 45017 | V36: 45047 | W36: 45078 | X36: 45108 | Y36: 45139 | Z36: 45170 | AA36: 45200 | AB36: 45231 | AC36: 45261 | AD36: 45292 | AE36: 45323 | AF36: 45352 | AG36: 45383 | AH36: 45413 | AI36: 45444 | AJ36: 45474 | AK36: 45505 | AL36: 45536
A37: BAYGON | B37: 0.50340482 | C37: 0.61271121 | D37: 0.63856232 | E37: 0.90642982 | F37: 1.1620274 | G37: 1.2599868 | H37: 1.3147476 | I37: 1.1123 | J37: 0.90884759 | K37: 0.52834809 | L37: 0.49925005 | M37: 0.57655747 | N37: 0.5210518 | O37: 0.68732549 | P37: 0.71078518 | Q37: 0.84314662 | R37: 0.93917268 | S37: 1.3686114 | T37: 1.3862629 | U37: 1.0657426 | V37: 0.93657374 | W37: 0.88816951 | X37: 0.77129385 | Y37: 0.67421174 | Z37: 0.63973346 | AA37: 0.71751327 | AB37: 0.62714378 | AC37: 0.86239752 | AD37: 0.88814903 | AE37: 0.98415559 | AF37: 1.2498707 | AG37: 1.3050739 | AH37: 1.272283 | AI37: 1.0013361 | AJ37: 0.73485134 | AK37: 0.52228492 | AL37: 0.42900402
A38: FUYI | B38: 0.54495612 | C38: 0.73418984 | D38: 0.80752112 | E38: 0.76240303 | F38: 1.0265088 | G38: 1.3033559 | H38: 1.3409247 | I38: 1.3463543 | J38: 1.053235 | K38: 0.6550106 | L38: 0.59148686 | M38: 0.53137865 | N38: 0.61234247 | O38: 0.68062828 | P38: 0.68900587 | Q38: 0.82428915 | R38: 0.95563047 | S38: 1.0097809 | T38: 1.0630758 | U38: 0.94768829 | V38: 0.94874614 | W38: 0.69962978 | X38: 0.53095631 | Y38: 0.48762767 | Z38: 0.60679597 | AA38: 0.66074123 | AB38: 0.70819077 | AC38: 1.0139212 | AD38: 1.1166703 | AE38: 1.1595219 | AF38: 1.3036869 | AG38: 1.4882064 | AH38: 1.2491274 | AI38: 1.1115629 | AJ38: 0.75503314 | AK38: 0.54383982 | AL38: 0.30066709
A39: RAID | B39: 0.56098833 | C39: 0.68531561 | D39: 0.77808791 | E39: 0.8924597 | F39: 1.1562594 | G39: 1.2076279 | H39: 1.0879547 | I39: 0.99943802 | J39: 0.76876736 | K39: 0.56733957 | L39: 0.482835 | M39: 0.44118055 | N39: 0.41325404 | O39: 0.49163714 | P39: 0.64991537 | Q39: 0.83510135 | R39: 1.1669659 | S39: 1.1334684 | T39: 1.283488 | U39: 1.1391487 | V39: 1.0523241 | W39: 0.82055245 | X39: 0.65604949 | Y39: 0.5829985 | Z39: 0.56053688 | AA39: 0.53897183 | AB39: 0.53588145 | AC39: 0.89478273 | AD39: 1.0094272 | AE39: 1.1843768 | AF39: 1.4189587 | AG39: 1.5076908 | AH39: 1.2016344 | AI39: 0.88250104 | AJ39: 0.71675518 | AK39: 0.40240557 | AL39: 0.33630886
A51: Pesticidas (Resto) | B51: 44440 | C51: 44470 | D51: 44501 | E51: 44531 | F51: 44562 | G51: 44593 | H51: 44621 | I51: 44652 | J51: 44682 | K51: 44713 | L51: 44743 | M51: 44774 | N51: 44805 | O51: 44835 | P51: 44866 | Q51: 44896 | R51: 44927 | S51: 44958 | T51: 44986 | U51: 45017 | V51: 45047 | W51: 45078 | X51: 45108 | Y51: 45139 | Z51: 45170 | AA51: 45200 | AB51: 45231 | AC51: 45261 | AD51: 45292 | AE51: 45323 | AF51: 45352 | AG51: 45383 | AH51: 45413 | AI51: 45444 | AJ51: 45474 | AK51: 45505 | AL51: 45536
A52: BAYGON | B52: 0.43990083 | C52: 0.64797943 | D52: 0.61046735 | E52: 0.74197656 | F52: 1.0335937 | G52: 1.0333608 | H52: 0.997906 | I52: 0.84641334 | J52: 0.47775717 | K52: 0.38780823 | L52: 0.43846293 | M52: 0.36850497 | N52: 0.41839457 | O52: 0.39555926 | P52: 0.71197161 | Q52: 0.95017643 | R52: 0.85125268 | S52: 0.79333443 | T52: 0.81219636 | U52: 0.52231556 | V52: 0.53209137 | W52: 0.36651922 | X52: 0.39068755 | Y52: 0.51390052 | Z52: 0.36040261 | AA52: 0.46064901 | AB52: 0.50915754 | AC52: 0.94195518 | AD52: 1.1776638 | AE52: 1.1301984 | AF52: 1.392985 | AG52: 1.4286116 | AH52: 1.1146393 | AI52: 0.70803356 | AJ52: 0.76880408 | AK52: 0.4928813 | AL52: 0.48052214
A53: FUYI | B53: 0.24578544 | C53: 0.47827672 | D53: 0.55559955 | E53: 0.98892516 | F53: 1.1852016 | G53: 1.2165544 | H53: 1.0580453 | I53: 0.97443386 | J53: 0.69321529 | K53: 0.43508589 | L53: 0.35161554 | M53: 0.30080966 | N53: 0.32133519 | O53: 0.38318225 | P53: 0.48895631 | Q53: 0.8145624 | R53: 0.88599957 | S53: 1.1765658 | T53: 1.1600077 | U53: 0.86752085 | V53: 0.72705145 | W53: 0.51976128 | X53: 0.37110429 | Y53: 0.33317493 | Z53: 0.3054129 | AA53: 0.41994798 | AB53: 0.63317983 | AC53: 0.9240339 | AD53: 1.0971821 | AE53: 1.0706325 | AF53: 1.467689 | AG53: 1.6597826 | AH53: 1.1471234 | AI53: 1.0034307 | AJ53: 0.74285982 | AK53: 0.40442247 | AL53: 0.2781227
A54: RAID | B54: 0.34679801 | C54: 0.49113454 | D54: 0.63071683 | E54: 0.79260409 | F54: 1.1419197 | G54: 1.0804268 | H54: 0.89235126 | I54: 0.77070521 | J54: 0.58421987 | K54: 0.38445326 | L54: 0.33930048 | M54: 0.34497376 | N54: 0.33492001 | O54: 0.41697508 | P54: 0.55480104 | Q54: 0.76572149 | R54: 0.88332626 | S54: 0.91501403 | T54: 0.94695035 | U54: 0.77677238 | V54: 0.62816436 | W54: 0.46435583 | X54: 0.40131713 | Y54: 0.32169295 | Z54: 0.34853756 | AA54: 0.42422298 | AB54: 0.53443043 | AC54: 0.85590919 | AD54: 1.0731024 | AE54: 1.0857557 | AF54: 1.3050474 | AG54: 1.3011915 | AH54: 0.98231206 | AI54: 0.71087045 | AJ54: 0.54540849 | AK54: 0.39362751 | AL54: 0.31122801
A65: Facts | B65: $
A66: CATEGORY | B66: (Todas)
A67: SEGMENT | B67: (Todas)
A68: FORM | B68: (Todas)
A70: Markets | B70: BRAND | C70: Suma de Sep 21 - w/e 22/09/21 | D70: Suma de Oct 21 - w/e 23/10/21 | E70: Suma de Nov 21 - w/e 22/11/21 | F70: Suma de Dec 21 - w/e 23/12/21 | G70: Suma de Jan 22 - w/e 23/01/22 | H70: Suma de Feb 22 - w/e 20/02/22 | I70: Suma de Mar 22 - w/e 23/03/22 | J70: Suma de Apr 22 - w/e 22/04/22 | K70: Suma de May 22 - w/e 23/05/22 | L70: Suma de Jun 22 - w/e 22/06/22 | M70: Suma de Jul 22 - w/e 23/07/22 | N70: Suma de Aug 22 - w/e 23/08/22 | O70: Suma de Sep 22 - w/e 22/09/22 | P70: Suma de Oct 22 - w/e 23/10/22 | Q70: Suma de Nov 22 - w/e 22/11/22 | R70: Suma de Dec 22 - w/e 23/12/22 | S70: Suma de Jan 23 - w/e 23/01/23 | T70: Suma de Feb 23 - w/e 20/02/23 | U70: Suma de Mar 23 - w/e 23/03/23 | V70: Suma de Apr 23 - w/e 22/04/23 | W70: Suma de May 23 - w/e 23/05/23 | X70: Suma de Jun 23 - w/e 22/06/23 | Y70: Suma de Jul 23 - w/e 23/07/23 | Z70: Suma de Aug 23 - w/e 23/08/23 | AA70: Suma de Sep 23 - w/e 22/09/23 | AB70: Suma de Oct 23 - w/e 23/10/23 | AC70: Suma de Nov 23 - w/e 22/11/23 | AD70: Suma de Dec 23 - w/e 23/12/23 | AE70: Suma de Jan 24 - w/e 23/01/24 | AF70: Suma de Feb 24 - w/e 21/02/24 | AG70: Suma de Mar 24 - w/e 23/03/24 | AH70: Suma de Apr 24 - w/e 22/04/24 | AI70: Suma de May 24 - w/e 23/05/24 | AJ70: Suma de Jun 24 - w/e 22/06/24 | AK70: Suma de Jul 24 - w/e 23/07/24 | AL70: Suma de Aug 24 - w/e 23/08/24 | AM70: Suma de Sep 24 - w/e 22/09/24
A71: T.URUGUAY INCT | B71: BAYGON | C71: 1284741.6 | D71: 1947028.3 | E71: 3039580.2 | F71: 4239274.3 | G71: 5375320.8 | H71: 5807492.8 | I71: 4959629.9 | J71: 3828356.2 | K71: 2462722.1 | L71: 1368331.6 | M71: 1219277.4 | N71: 1313184.2 | O71: 1410086.9 | P71: 2590798.5 | Q71: 3736463.1 | R71: 4655987.4 | S71: 5645321.1 | T71: 5192021 | U71: 4571072.3 | V71: 3318770.4 | W71: 2640215.3 | X71: 2185538.9 | Y71: 1787618.6 | Z71: 1641514.5 | AA71: 1499623.7 | AB71: 2009797.7 | AC71: 2814339.7 | AD71: 4232988.8 | AE71: 5541971 | AF71: 5883937.4 | AG71: 6259930.9 | AH71: 6379274.8 | AI71: 3938743.1 | AJ71: 2974879.8 | AK71: 2357312.4 | AL71: 1557519.3 | AM71: 1432328.7
B72: FUYI | C72: 2405149.6 | D72: 5365126.2 | E72: 8892143.8 | F72: 11494780 | G72: 17042232 | H72: 15051148 | I72: 14415313 | J72: 10106990 | K72: 6369208.2 | L72: 3210664.9 | M72: 2522014.9 | N72: 2502460.9 | O72: 3079319.7 | P72: 4676380.5 | Q72: 8493535.5 | R72: 12294348 | S72: 15153335 | T72: 14211141 | U72: 13845031 | V72: 9713933.3 | W72: 7415134.8 | X72: 4652205.4 | Y72: 3067505.9 | Z72: 3002260.4 | AA72: 3361541.2 | AB72: 5804560.8 | AC72: 8874178.2 | AD72: 14817419 | AE72: 20259730 | AF72: 18471918 | AG72: 21857559 | AH72: 22380667 | AI72: 11718710 | AJ72: 7428459.5 | AK72: 4753277.4 | AL72: 3200428.2 | AM72: 2775735.8
B73: OFF! | C73: 2457039.6 | D73: 5641045.3 | E73: 9972934.5 | F73: 13340053 | G73: 24953202 | H73: 21514877 | I73: 15463908 | J73: 8190450.6 | K73: 4191700 | L73: 2715679.7 | M73: 2448339.4 | N73: 2146427.7 | O73: 2483913.2 | P73: 3219838 | Q73: 8186100.6 | R73: 16400067 | S73: 20976524 | T73: 18534341 | U73: 18585656 | V73: 11074714 | W73: 7486951.4 | X73: 4303854.1 | Y73: 3630027.1 | Z73: 2741496.9 | AA73: 3097629.4 | AB73: 5181341.3 | AC73: 9529934.9 | AD73: 25395375 | AE73: 50663064 | AF73: 38380148 | AG73: 58442738 | AH73: 86488531 | AI73: 27467447 | AJ73: 11255265 | AK73: 6661162.7 | AL73: 4486090.5 | AM73: 4690959.7
B74: RAID | C74: 14471920 | D74: 24436484 | E74: 38759121 | F74: 49600575 | G74: 68369098 | H74: 57994568 | I74: 49505417 | J74: 34160195 | K74: 21668689 | L74: 13330203 | M74: 10878541 | N74: 10903169 | O74: 13202229 | P74: 19821165 | Q74: 37223675 | R74: 54551078 | S74: 63868674 | T74: 56161608 | U74: 56991912 | V74: 40901329 | W74: 30451374 | X74: 20277027 | Y74: 15356126 | Z74: 13637240 | AA74: 14912391 | AB74: 23397799 | AC74: 35193374 | AD74: 61434437 | AE74: 77407075 | AF74: 68109538 | AG74: 74497528 | AH74: 70655495 | AI74: 42712897 | AJ74: 27097976 | AK74: 19015537 | AL74: 13344645 | AM74: 13051023
A75: Total general | C75: 20618851 | D75: 37389684 | E75: 60663779 | F75: 78674683 | G75: 1.1573985e+08 | H75: 1.0036809e+08 | I75: 84344268 | J75: 56285992 | K75: 34692319 | L75: 20624879 | M75: 17068173 | N75: 16865242 | O75: 20175549 | P75: 30308182 | Q75: 57639774 | R75: 87901479 | S75: 1.0564385e+08 | T75: 94099111 | U75: 93993672 | V75: 65008747 | W75: 47993675 | X75: 31418626 | Y75: 23841278 | Z75: 21022512 | AA75: 22871186 | AB75: 36393499 | AC75: 56411826 | AD75: 1.0588022e+08 | AE75: 1.5387184e+08 | AF75: 1.3084554e+08 | AG75: 1.6105776e+08 | AH75: 1.8590397e+08 | AI75: 85837797 | AJ75: 48756581 | AK75: 32787290 | AL75: 22588683 | AM75: 21950047
AL78: =+SUM(P75:AA75) -> 6.817421e+08 | AM78: =+SUM(AB75:AM75) -> 1.042285e+09

Sheet Dataset
A1: Markets | B1: PEST CONTROL | C1: MANUFACTURER | D1: CATEGORY | E1: SEGMENT | F1: BRAND | G1: FORM | H1: Facts | I1: Sep 21 - w/e 22/09/21 | J1: Oct 21 - w/e 23/10/21 | K1: Nov 21 - w/e 22/11/21 | L1: Dec 21 - w/e 23/12/21 | M1: Jan 22 - w/e 23/01/22 | N1: Feb 22 - w/e 20/02/22 | O1: Mar 22 - w/e 23/03/22 | P1: Apr 22 - w/e 22/04/22 | Q1: May 22 - w/e 23/05/22 | R1: Jun 22 - w/e 22/06/22 | S1: Jul 22 - w/e 23/07/22 | T1: Aug 22 - w/e 23/08/22 | U1: Sep 22 - w/e 22/09/22 | V1: Oct 22 - w/e 23/10/22 | W1: Nov 22 - w/e 22/11/22 | X1: Dec 22 - w/e 23/12/22 | Y1: Jan 23 - w/e 23/01/23 | Z1: Feb 23 - w/e 20/02/23 | AA1: Mar 23 - w/e 23/03/23 | AB1: Apr 23 - w/e 22/04/23 | AC1: May 23 - w/e 23/05/23 | AD1: Jun 23 - w/e 22/06/23 | AE1: Jul 23 - w/e 23/07/23 | AF1: Aug 23 - w/e 23/08/23 | AG1: Sep 23 - w/e 22/09/23 | AH1: Oct 23 - w/e 23/10/23 | AI1: Nov 23 - w/e 22/11/23 | AJ1: Dec 23 - w/e 23/12/23 | AK1: Jan 24 - w/e 23/01/24 | AL1: Feb 24 - w/e 21/02/24 | AM1: Mar 24 - w/e 23/03/24 | AN1: Apr 24 - w/e 22/04/24 | AO1: May 24 - w/e 23/05/24 | AP1: Jun 24 - w/e 22/06/24 | AQ1: Jul 24 - w/e 23/07/24 | AR1: Aug 24 - w/e 23/08/24 | AS1: Sep 24 - w/e 22/09/24 | AT1: Sep 24 - w/e 22/09/24
A2: T.URUGUAY TRADICIONALES | B2: PEST CONTROL | C2: SC JOHNSON | D2: PERSONAL REPELLENT | E2: MOSQUITO | F2: FUYI | G2: AEROSOL | H2: Units | I2: 64.184 | J2: 100.345 | K2: 242.234 | L2: 466.412 | M2: 638.763 | N2: 631.063 | O2: 651.21 | P2: 326.766 | Q2: 468.013 | R2: 342.786 | S2: 379.388 | T2: 185.346 | U2: 123.609 | V2: 178.359 | W2: 379.907 | X2: 603.267 | Y2: 547.457 | Z2: 145.43 | AA2: 367.898 | AB2: 207.412 | AC2: 205.611 | AD2: 106.342 | AE2: 122.92 | AF2: 373.45 | AG2: 110.089 | AH2: 108.449 | AI2: 209.038 | AJ2: 455.3 | AK2: 774.826 | AL2: 746.469 | AM2: 1669.853 | AN2: 1442.46 | AO2: 902.833 | AP2: 441.326 | AQ2: 420.529 | AR2: 238.692 | AS2: 327.142 | AT2: 327.142
A3: T.URUGUAY TRADICIONALES | B3: PEST CONTROL | C3: SC JOHNSON | D3: PERSONAL REPELLENT | E3: MOSQUITO | F3: FUYI | G3: AEROSOL | H3: $ | I3: 12074.562 | J3: 21072.505 | K3: 51309.743 | L3: 100476.76 | M3: 120505.98 | N3: 110014.56 | O3: 106027.68 | P3: 47374.111 | Q3: 88238.662 | R3: 66675.139 | S3: 71963.817 | T3: 37648.789 | U3: 26217.28 | V3: 35430.729 | W3: 68719.61 | X3: 105367.93 | Y3: 95440.762 | Z3: 23861.161 | AA3: 67266.099 | AB3: 37915.577 | AC3: 35774.926 | AD3: 17027.746 | AE3: 22155.042 | AF3: 74412.895 | AG3: 19555.704 | AH3: 20063.104 | AI3: 38403.46 | AJ3: 75918.379 | AK3: 129733.53 | AL3: 124846.74 | AM3: 308004.73 | AN3: 285971.62 | AO3: 179050.84 | AP3: 77855.164 | AQ3: 71990.056 | AR3: 46256.623 | AS3: 59177.552 | AT3: 59177.552
A4: T.URUGUAY TRADICIONALES | B4: PEST CONTROL | C4: SC JOHNSON | D4: PERSONAL REPELLENT | E4: MOSQUITO | F4: FUYI | G4: AEROSOL | H4: (FE) Shr - Product | I4: 0.046 | J4: 0.06 | K4: 0.117 | L4: 0.169 | M4: 0.203 | N4: 0.186 | O4: 0.201 | P4: 0.128 | Q4: 0.228 | R4: 0.235 | S4: 0.311 | T4: 0.168 | U4: 0.114 | V4: 0.14 | W4: 0.208 | X4: 0.244 | Y4: 0.18 | Z4: 0.051 | AA4: 0.123 | AB4: 0.086 | AC4: 0.095 | AD4: 0.061 | AE4: 0.08 | AF4: 0.25 | AG4: 0.071 | AH4: 0.062 | AI4: 0.096 | AJ4: 0.17 | AK4: 0.253 | AL4: 0.238 | AM4: 0.443 | AN4: 0.43 | AO4: 0.313 | AP4: 0.174 | AQ4: 0.195 | AR4: 0.157 | AS4: 0.314 | AT4: 0.096
A5: T.URUGUAY TRADICIONALES | B5: PEST CONTROL | C5: SC JOHNSON | D5: PERSONAL REPELLENT | E5: MOSQUITO | F5: FUYI | G5: AEROSOL | H5: Wghtd Dist Handling | I5: 4.424 | J5: 6.078 | K5: 7.312 | L5: 6.992 | M5: 8.594 | N5: 9.117 | O5: 10.248 | P5: 11.611 | Q5: 13.416 | R5: 14.039 | S5: 17.233 | T5: 17.155 | U5: 15.773 | V5: 14.458 | W5: 14.829 | X5: 9.87 | Y5: 8.779 | Z5: 8.065 | AA5: 8.572 | AB5: 8.122 | AC5: 10.182 | AD5: 7.759 | AE5: 8.204 | AF5: 8.513 | AG5: 7.649 | AH5: 5.965 | AI5: 6.516 | AJ5: 7.683 | AK5: 9.606 | AL5: 10.852 | AM5: 15.023 | AN5: 15.852 | AO5: 12.584 | AP5: 11.103 | AQ5: 11.707 | AR5: 9.709 | AS5: 9.02 | AT5: 437.786
A6: T.URUGUAY TRADICIONALES | B6: PEST CONTROL | C6: SC JOHNSON | D6: PERSONAL REPELLENT | E6: MOSQUITO | F6: FUYI | G6: AEROSOL | H6: Numeric Distribution Handling (C) | I6: 3.8527033 | J6: 4.4002403 | K6: 5.0849243 | L6: 6.01099 | M6: 5.881392 | N6: 5.9677327 | O6: 4.8139226 | P6: 4.7566604 | Q6: 4.5100185 | R6: 4.4265204 | S6: 4.6981739 | T6: 4.2102993 | U6: 4.5402902 | V6: 4.4302915 | W6: 4.8239754 | X6: 4.7834399 | Y6: 3.3895473 | Z6: 3.3928448 | AA6: 4.7465691 | AB6: 5.4651258 | AC6: 5.6141875 | AD6: 5.4772747 | AE6: 5.8538852 | AF6: 4.8009812 | AG6: 3.2386336 | AH6: 3.7832645 | AI6: 4.3679462 | AJ6: 5.6231045 | AK6: 5.5504365 | AL6: 6.8308562 | AM6: 9.2025134 | AN6: 10.001254 | AO6: 8.0695134 | AP6: 6.1463007 | AQ6: 5.866254 | AR6: 5.1518527 | AS6: 5.3466192 | AT6: 9.02
A7: T.URUGUAY TRADICIONALES | B7: PEST CONTROL | C7: SC JOHNSON | D7: PERSONAL REPELLENT | E7: MOSQUITO | F7: FUYI | G7: AEROSOL | H7: Stocks Forward Units Shr - Product | I7: 0.332 | J7: 0.5 | K7: 0.503 | L7: 0.492 | M7: 0.365 | N7: 0.343 | O7: 0.275 | P7: 0.464 | Q7: 0.308 | R7: 0.323 | S7: 0.337 | T7: 0.337 | U7: 0.353 | V7: 0.3 | W7: 0.331 | X7: 0.275 | Y7: 0.159 | Z7: 0.214 | AA7: 0.303 | AB7: 0.384 | AC7: 0.399 | AD7: 0.398 | AE7: 0.391 | AF7: 0.247 | AG7: 0.199 | AH7: 0.218 | AI7: 0.233 | AJ7: 0.403 | AK7: 0.407 | AL7: 0.394 | AM7: 0.41 | AN7: 0.606 | AO7: 0.431 | AP7: 0.376 | AQ7: 0.281 | AR7: 0.321 | AS7: 0.229 | AT7: 5.3466192
A8: T.URUGUAY TRADICIONALES | B8: PEST CONTROL | C8: SC JOHNSON | D8: PERSONAL REPELLENT | E8: MOSQUITO | F8: FUYI | G8: LIQUID BOTTLE | H8: Units | I8: 37.649 | J8: 44.379 | K8: 0 | L8: 8.706 | M8: 17.412 | N8: 17.412 | O8: 0 | P8: 9.297 | Q8: 20.382 | R8: 0 | S8: 10.191 | T8: 0 | U8: 0 | V8: 0 | W8: 0 | X8: 0 | Y8: 0 | Z8: 0 | AA8: 0 | AB8: 0 | AC8: 0 | AD8: 0 | AE8: 0 | AF8: 0 | AG8: 0 | AH8: 0 | AI8: 0 | AJ8: 0 | AK8: 0 | AL8: 0 | AM8: 0 | AN8: 0 | AO8: 0 | AP8: 0 | AQ8: 0 | AR8: 0 | AS8: 0 | AT8: 0
A9: T.URUGUAY TRADICIONALES | B9: PEST CONTROL | C9: SC JOHNSON | D9: PERSONAL REPELLENT | E9: MOSQUITO | F9: FUYI | G9: LIQUID BOTTLE | H9: $ | I9: 2823.683 | J9: 3949.711 | K9: 0 | L9: 740.024 | M9: 1480.047 | N9: 1480.047 | O9: 0 | P9: 650.765 | Q9: 1732.439 | R9: 0 | S9: 866.22 | T9: 0 | U9: 0 | V9: 0 | W9: 0 | X9: 0 | Y9: 0 | Z9: 0 | AA9: 0 | AB9: 0 | AC9: 0 | AD9: 0 | AE9: 0 | AF9: 0 | AG9: 0 | AH9: 0 | AI9: 0 | AJ9: 0 | AK9: 0 | AL9: 0 | AM9: 0 | AN9: 0 | AO9: 0 | AP9: 0 | AQ9: 0 | AR9: 0 | AS9: 0 | AT9: 0
A10: T.URUGUAY TRADICIONALES | B10: PEST CONTROL | C10: SC JOHNSON | D10: PERSONAL REPELLENT | E10: MOSQUITO | F10: FUYI | G10: LIQUID BOTTLE | H10: (FE) Shr - Product | I10: 0.01 | J10: 0.01 | K10: 0 | L10: 0.001 | M10: 0.002 | N10: 0.002 | O10: 0 | P10: 0.001 | Q10: 0.004 | R10: 0 | S10: 0.003 | T10: 0 | U10: 0 | V10: 0 | W10: 0 | X10: 0 | Y10: 0 | Z10: 0 | AA10: 0 | AB10: 0 | AC10: 0 | AD10: 0 | AE10: 0 | AF10: 0 | AG10: 0 | AH10: 0 | AI10: 0 | AJ10: 0 | AK10: 0 | AL10: 0 | AM10: 0 | AN10: 0 | AO10: 0 | AP10: 0 | AQ10: 0 | AR10: 0 | AS10: 0 | AT10: 0
A11: T.URUGUAY TRADICIONALES | B11: PEST CONTROL | C11: SC JOHNSON | D11: PERSONAL REPELLENT | E11: MOSQUITO | F11: FUYI | G11: LIQUID BOTTLE | H11: Wghtd Dist Handling | I11: 1 | J11: 0.488 | K11: 0 | L11: 0.01 | M11: 0.025 | N11: 0.013 | O11: 0.276 | P11: 0.232 | Q11: 0.031 | R11: 0 | S11: 0.075 | T11: 0 | U11: 0 | V11: 0 | W11: 0 | X11: 0 | Y11: 0 | Z11: 0 | AA11: 0 | AB11: 0 | AC11: 0 | AD11: 0 | AE11: 0 | AF11: 0 | AG11: 0 | AH11: 0 | AI11: 0 | AJ11: 0 | AK11: 0 | AL11: 0 | AM11: 0 | AN11: 0 | AO11: 0 | AP11: 0 | AQ11: 0 | AR11: 0 | AS11: 0 | AT11: 0
A12: T.URUGUAY TRADICIONALES | B12: PEST CONTROL | C12: SC JOHNSON | D12: PERSONAL REPELLENT | E12: MOSQUITO | F12: FUYI | G12: LIQUID BOTTLE | H12: Numeric Distribution Handling (C) | I12: 0.5979892 | J12: 0.1381697 | K12: 0 | L12: 0.139341 | M12: 0.139341 | N12: 0.139341 | O12: 0.2786822 | P12: 0.2786819 | Q12: 0.1562028 | R12: 0.156203 | S12: 0.156203 | T12: 0 | U12: 0 | V12: 0 | W12: 0 | X12: 0 | Y12: 0 | Z12: 0 | AA12: 0 | AB12: 0 | AC12: 0 | AD12: 0 | AE12: 0 | AF12: 0 | AG12: 0 | AH12: 0 | AI12: 0 | AJ12: 0 | AK12: 0 | AL12: 0 | AM12: 0 | AN12: 0 | AO12: 0 | AP12: 0 | AQ12: 0 | AR12: 0 | AS12: 0 | AT12: 0
A13: T.URUGUAY TRADICIONALES | B13: PEST CONTROL | C13: SC JOHNSON | D13: PERSONAL REPELLENT | E13: MOSQUITO | F13: FUYI | G13: LIQUID BOTTLE | H13: Stocks Forward Units Shr - Product | I13: 0 | J13: 0 | K13: 0 | L13: 0.009 | M13: 0.013 | N13: 0.013 | O13: 0.017 | P13: 0.014 | Q13: 0.005 | R13: 0.005 | S13: 0 | T13: 0 | U13: 0 | V13: 0 | W13: 0 | X13: 0 | Y13: 0 | Z13: 0 | AA13: 0 | AB13: 0 | AC13: 0 | AD13: 0 | AE13: 0 | AF13: 0 | AG13: 0 | AH13: 0 | AI13: 0 | AJ13: 0 | AK13: 0 | AL13: 0 | AM13: 0 | AN13: 0 | AO13: 0 | AP13: 0 | AQ13: 0 | AR13: 0 | AS13: 0 | AT13: 0
... A1027: T.URUGUAY AUTOSERVICIOS | B1027: PEST CONTROL | C1027: SC JOHNSON | D1027: MULTI INSECT KILLER | E1027: OTHER FLYING & CRAWLING | F1027: RAID | G1027: AEROSOL | H1027: Stocks Forward Units Shr - Product | I1027: 1.322 | J1027: 1.19 | K1027: 1.478 | L1027: 1.267 | M1027: 1.43 | N1027: 1.344 | O1027: 1.309 | P1027: 1.189 | Q1027: 1.146 | R1027: 1.063 | S1027: 1.099 | T1027: 0.916 | U1027: 1.019 | V1027: 1.163 | W1027: 0.968 | X1027: 0.837 | Y1027: 0.864 | Z1027: 0.693 | AA1027: 0.687 | AB1027: 0.613 | AC1027: 0.616 | AD1027: 0.58 | AE1027: 0.528 | AF1027: 0.565 | AG1027: 0.518 | AH1027: 0.704 | AI1027: 0.577 | AJ1027: 0.525 | AK1027: 0.633 | AL1027: 0.588 | AM1027: 0.738 | AN1027: 0.573 | AO1027: 0.859 | AP1027: 1.001 | AQ1027: 0.911 | AR1027: 1.045 | AS1027: 1.146 | AT1027: 23.83672

Sheet D.Inventario
A1: Markets | B1: (Varios elementos)
A2: Facts | B2: Stocks Forward Units
A3: CATEGORY | B3: (Varios elementos)
A4: SEGMENT | B4: (Todas)
A5: FORM | B5: (Todas)
A7: Etiquetas de fila | B7: Suma de Sep 21 - w/e 22/09/21 | C7: Suma de Oct 21 - w/e 23/10/21 | D7: Suma de Nov 21 - w/e 22/11/21 | E7: Suma de Dec 21 - w/e 23/12/21 | F7: Suma de Jan 22 - w/e 23/01/22 | G7: Suma de Feb 22 - w/e 20/02/22 | H7: Suma de Mar 22 - w/e 23/03/22 | I7: Suma de Apr 22 - w/e 22/04/22 | J7: Suma de May 22 - w/e 23/05/22 | K7: Suma de Jun 22 - w/e 22/06/22 | L7: Suma de Jul 22 - w/e 23/07/22 | M7: Suma de Aug 22 - w/e 23/08/22 | N7: Suma de Sep 22 - w/e 22/09/22 | O7: Suma de Oct 22 - w/e 23/10/22 | P7: Suma de Nov 22 - w/e 22/11/22 | Q7: Suma de Dec 22 - w/e 23/12/22 | R7: Suma de Jan 23 - w/e 23/01/23 | S7: Suma de Feb 23 - w/e 20/02/23 | T7: Suma de Mar 23 - w/e 23/03/23 | U7: Suma de Apr 23 - w/e 22/04/23 | V7: Suma de May 23 - w/e 23/05/23 | W7: Suma de Jun 23 - w/e 22/06/23 | X7: Suma de Jul 23 - w/e 23/07/23 | Y7: Suma de Aug 23 - w/e 23/08/23 | Z7: Suma de Sep 23 - w/e 22/09/23 | AA7: Suma de Oct 23 - w/e 23/10/23 | AB7: Suma de Nov 23 - w/e 22/11/23 | AC7: Suma de Dec 23 - w/e 23/12/23 | AD7: Suma de Jan 24 - w/e 23/01/24 | AE7: Suma de Feb 24 - w/e 21/02/24 | AF7: Suma de Mar 24 - w/e 23/03/24 | AG7: Suma de Apr 24 - w/e 22/04/24 | AH7: Suma de May 24 - w/e 23/05/24 | AI7: Suma de Jun 24 - w/e 22/06/24 | AJ7: Suma de Jul 24 - w/e 23/07/24 | AK7: Suma de Aug 24 - w/e 23/08/24 | AL7: Suma de Sep 24 - w/e 22/09/24
A8: BAYGON | B8: 3727.181 | C8: 3848.599 | D8: 6120.863 | E8: 4922.607 | F8: 3764.487 | G8: 4245.521 | H8: 4252.146 | I8: 4153.134 | J8: 4105.661 | K8: 3829.55 | L8: 3441.641 | M8: 3637.799 | N8: 4331.299 | O8: 5090.092 | P8: 4943.898 | Q8: 4730.071 | R8: 4947.363 | S8: 3806.909 | T8: 3199.512 | U8: 3201.959 | V8: 3726.781 | W8: 4727.261 | X8: 4566.703 | Y8: 4085.997 | Z8: 4389.602 | AA8: 4251.875 | AB8: 5460.255 | AC8: 4800.48 | AD8: 4427.037 | AE8: 5276.825 | AF8: 3694.843 | AG8: 3798.577 | AH8: 3526.922 | AI8: 4074.071 | AJ8: 3490.732 | AK8: 3132.594 | AL8: 3605.118
A9: FUYI | B9: 8778.905 | C9: 10955.553 | D9: 14169.925 | E9: 15494.039 | F9: 17194.012 | G9: 14416.961 | H9: 16662.699 | I9: 14384.027 | J9: 14836.665 | K9: 13530.556 | L9: 13047.748 | M9: 13735.789 | N9: 12810.259 | O9: 14208.68 | P9: 13467.418 | Q9: 11761.018 | R9: 12782.46 | S9: 10449.509 | T9: 10312.202 | U9: 10441.59 | V9: 11468.176 | W9: 10773.946 | X9: 9307.478 | Y9: 9610.528 | Z9: 10071.215 | AA9: 10631.793 | AB9: 10462.29 | AC9: 11890.028 | AD9: 13422.899 | AE9: 14775.041 | AF9: 13408.944 | AG9: 12578.137 | AH9: 12583.065 | AI9: 12014.868 | AJ9: 11927.914 | AK9: 12655.276 | AL9: 10847.029
A10: RAID | B10: 62521.192 | C10: 58793.672 | D10: 63888.206 | E10: 69522.052 | F10: 67210.968 | G10: 65161.31 | H10: 65144.327 | I10: 60075.991 | J10: 56174.837 | K10: 57852.729 | L10: 54867.352 | M10: 55960.181 | N10: 58226.819 | O10: 60164.658 | P10: 73551.681 | Q10: 72076.607 | R10: 73150.009 | S10: 67605.22 | T10: 68471.99 | U10: 63172.393 | V10: 63874.332 | W10: 61104.938 | X10: 62089.015 | Y10: 61254.936 | Z10: 65197.412 | AA10: 70412.591 | AB10: 75981.487 | AC10: 71329.557 | AD10: 74505.323 | AE10: 72842.572 | AF10: 75470.132 | AG10: 71969.05 | AH10: 67640.379 | AI10: 69522.507 | AJ10: 66083.583 | AK10: 65933.898 | AL10: 66752.148
A11: Total general | B11: 75027.278 | C11: 73597.824 | D11: 84178.994 | E11: 89938.698 | F11: 88169.467 | G11: 83823.792 | H11: 86059.172 | I11: 78613.152 | J11: 75117.163 | K11: 75212.835 | L11: 71356.741 | M11: 73333.769 | N11: 75368.377 | O11: 79463.43 | P11: 91962.997 | Q11: 88567.696 | R11: 90879.832 | S11: 81861.638 | T11: 81983.704 | U11: 76815.942 | V11: 79069.289 | W11: 76606.145 | X11: 75963.196 | Y11: 74951.461 | Z11: 79658.229 | AA11: 85296.259 | AB11: 91904.032 | AC11: 88020.065 | AD11: 92355.259 | AE11: 92894.438 | AF11: 92573.919 | AG11: 88345.764 | AH11: 83750.366 | AI11: 85611.446 | AJ11: 81502.229 | AK11: 81721.768 | AL11: 81204.295
A15: Repelentes | B15: 44440 | C15: 44470 | D15: 44501 | E15: 44531 | F15: 44562 | G15: 44593 | H15: 44621 | I15: 44652 | J15: 44682 | K15: 44713 | L15: 44743 | M15: 44774 | N15: 44805 | O15: 44835 | P15: 44866 | Q15: 44896 | R15: 44927 | S15: 44958 | T15: 44986 | U15: 45017 | V15: 45047 | W15: 45078 | X15: 45108 | Y15: 45139 | Z15: 45170 | AA15: 45200 | AB15: 45231 | AC15: 45261 | AD15: 45292 | AE15: 45323 | AF15: 45352 | AG15: 45383 | AH15: 45413 | AI15: 45444 | AJ15: 45474 | AK15: 45505 | AL15: 45536 | AM15: UAM-1 | AN15: UAM | AO15: Var. UAM | AP15: Aporte UAM-1 | AQ15: Aporte UAM
A16: FUYI | B16: 3189.318 | C16: 3180.318 | D16: 3548.939 | E16: 3495.548 | F16: 3536.964 | G16: 3120.244 | H16: 3516.089 | I16: 3520.539 | J16: 2940.848 | K16: 2561.228 | L16: 2793.493 | M16: 2863.95 | N16: 2776.621 | O16: 2295.5 | P16: 3813.369 | Q16: 3153.386 | R16: 3003.024 | S16: 3144.947 | T16: 3021.18 | U16: 3398.55 | V16: 3285.082 | W16: 3144.052 | X16: 3127.795 | Y16: 2598.321 | Z16: 2742.477 | AA16: 2689.788 | AB16: 2492.01 | AC16: 3154.632 | AD16: 3222.082 | AE16: 3386.15 | AF16: 4846.444 | AG16: 4569.409 | AH16: 4108.038 | AI16: 4515.76 | AJ16: 3694.939 | AK16: 3708.818 | AL16: 3352.874 | AM16: =+SUM(O16:Z16) -> 36727.683 | AN16: =+SUM(AA16:AL16) -> 43740.944 | AO16: =+AN16/AM16-1 -> 0.19095299 | AP16: =+AM16/$AM$18 -> 0.04582918 | AQ16: =+AN16/$AN$18 -> 0.061646355
A17: OFF! | B17: 54159.94 | C17: 50235.952 | D17: 57446.685 | E17: 60221.178 | F17: 58752.15 | G17: 60772.6 | H17: 58207.352 | I17: 54266.061 | J17: 54007.829 | K17: 54222.167 | L17: 54580.176 | M17: 57713.503 | N17: 57039.676 | O17: 58114.21 | P17: 68511.169 | Q17: 73901.766 | R17: 70352.853 | S17: 71841.593 | T17: 68158.727 | U17: 63167.113 | V17: 60074.615 | W17: 57429.534 | X17: 58015.361 | Y17: 57028.635 | Z17: 58080.626 | AA17: 62875.945 | AB17: 65068.729 | AC17: 66719.509 | AD17: 67577.584 | AE17: 66310.812 | AF17: 61722.465 | AG17: 53263.727 | AH17: 48418.868 | AI17: 45505.153 | AJ17: 43533.416 | AK17: 41690.382 | AL17: 43118.782 | AM17: =+SUM(O17:Z17) -> 764676.2 | AN17: =+SUM(AA17:AL17) -> 665805.37 | AO17: =+AN17/AM17-1 -> -0.12929764 | AP17: =+AM17/$AM$18 -> 0.95417082 | AQ17: =+AN17/$AN$18 -> 0.93835365
A18: Total general | B18: 57349.258 | C18: 53416.27 | D18: 60995.624 | E18: 63716.726 | F18: 62289.114 | G18: 63892.844 | H18: 61723.441 | I18: 57786.6 | J18: 56948.677 | K18: 56783.395 | L18: 57373.669 | M18: 60577.453 | N18: 59816.297 | O18: 60409.71 | P18: 72324.538 | Q18: 77055.152 | R18: 73355.877 | S18: 74986.54 | T18: 71179.907 | U18: 66565.663 | V18: 63359.697 | W18: 60573.586 | X18: 61143.156 | Y18: 59626.956 | Z18: 60823.103 | AA18: 65565.733 | AB18: 67560.739 | AC18: 69874.141 | AD18: 70799.666 | AE18: 69696.962 | AF18: 66568.909 | AG18: 57833.136 | AH18: 52526.906 | AI18: 50020.913 | AJ18: 47228.355 | AK18: 45399.2 | AL18: 46471.656 | AM18: =+SUM(O18:Z18) -> 801403.89 | AN18: =+SUM(AA18:AL18) -> 709546.32 | AO18: =+AN18/AM18-1 -> -0.11462082 | AP18: =+AM18/$AM$18 -> 1 | AQ18: =+AN18/$AN$18 -> 1
A36: Insecticida | B36: 44440 | C36: 44470 | D36: 44501 | E36: 44531 | F36: 44562 | G36: 44593 | H36: 44621 | I36: 44652 | J36: 44682 | K36: 44713 | L36: 44743 | M36: 44774 | N36: 44805 | O36: 44835 | P36: 44866 | Q36: 44896 | R36: 44927 | S36: 44958 | T36: 44986 | U36: 45017 | V36: 45047 | W36: 45078 | X36: 45108 | Y36: 45139 | Z36: 45170 | AA36: 45200 | AB36: 45231 | AC36: 45261 | AD36: 45292 | AE36: 45323 | AF36: 45352 | AG36: 45383 | AH36: 45413 | AI36: 45444 | AJ36: 45474 | AK36: 45505 | AL36: 45536 | AM36: UAM-1 | AN36: UAM | AO36: Var. UAM | AP36: Aporte UAM-1 | AQ36: Aporte UAM
A37: BAYGON | B37: 16587.058 | C37: 17694.039 | D37: 25221.175 | E37: 27988.307 | F37: 23182.123 | G37: 24597.009 | H37: 19839.86 | I37: 18757.725 | J37: 17839.156 | K37: 18413.548 | L37: 17619.866 | M37: 16769.369 | N37: 16330.359 | O37: 16779.743 | P37: 22889.104 | Q37: 25678.464 | R37: 26959.301 | S37: 19314.471 | T37: 17086.52 | U37: 16518.215 | V37: 16359.154 | W37: 15811.86 | X37: 14928.3 | Y37: 14241.434 | Z37: 13797.59 | AA37: 14556.22 | AB37: 18998.063 | AC37: 19581.347 | AD37: 20738.157 | AE37: 21182.047 | AF37: 21736.088 | AG37: 20730.501 | AH37: 15596.289 | AI37: 16790.431 | AJ37: 19087.756 | AK37: 17261.226 | AL37: 16079.91 | AM37: =+SUM(O37:Z37) -> 220364.16 | AN37: =+SUM(AA37:AL37) -> 222338.04 | AO37: =+AN37/AM37-1 -> 0.0089573506 | AP37: =+AM37/$AM$40 -> 0.22942817 | AQ37: =+AN37/$AN$40 -> 0.22833352
A38: FUYI | B38: 14739.673 | C38: 18228.912 | D38: 21949.016 | E38: 28385.295 | F38: 24440.071 | G38: 22686.115 | H38: 20440.038 | I38: 18486.491 | J38: 17357.524 | K38: 17430.124 | L38: 16397.076 | M38: 17875.005 | N38: 17499.686 | O38: 16938.062 | P38: 23368.56 | Q38: 24094.944 | R38: 25905.797 | S38: 22660.196 | T38: 22513.118 | U38: 20846.46 | V38: 19968.741 | W38: 19864.639 | X38: 20036.014 | Y38: 20567.102 | Z38: 19119.822 | AA38: 21577.948 | AB38: 23921.214 | AC38: 22553.816 | AD38: 21579.867 | AE38: 22397.34 | AF38: 22130.945 | AG38: 18896.865 | AH38: 17405.897 | AI38: 17468.114 | AJ38: 17598.213 | AK38: 17319.629 | AL38: 17170.11 | AM38: =+SUM(O38:Z38) -> 255883.45 | AN38: =+SUM(AA38:AL38) -> 240019.96 | AO38: =+AN38/AM38-1 -> -0.061995009 | AP38: =+AM38/$AM$40 -> 0.26640845 | AQ38: =+AN38/$AN$40 -> 0.24649225
A39: RAID | B39: 34438.112 | C39: 39372.268 | D39: 41985.815 | E39: 48634.892 | F39: 44074.564 | G39: 42195.871 | H39: 44342.175 | I39: 38839.163 | J39: 37154.781 | K39: 38197.006 | L39: 36998.254 | M39: 36583.36 | N39: 40339.516 | O39: 43355.339 | P39: 48864.422 | Q39: 51205.034 | R39: 46737.694 | S39: 41729.766 | T39: 40234.271 | U39: 37362.299 | V39: 34940.039 | W39: 33984.888 | X39: 35700.29 | Y39: 34607.974 | Z39: 35523.381 | AA39: 44674.784 | AB39: 52609.955 | AC39: 48734.108 | AD39: 50962.698 | AE39: 45492.985 | AF39: 45191.25 | AG39: 39523.755 | AH39: 38163.64 | AI39: 37576.222 | AJ39: 35427.402 | AK39: 37121.509 | AL39: 35906.101 | AM39: =+SUM(O39:Z39) -> 484245.4 | AN39: =+SUM(AA39:AL39) -> 511384.41 | AO39: =+AN39/AM39-1 -> 0.056043924 | AP39: =+AM39/$AM$40 -> 0.50416338 | AQ39: =+AN39/$AN$40 -> 0.52517422
A40: Total general | B40: 65764.843 | C40: 75295.219 | D40: 89156.006 | E40: 105008.49 | F40: 91696.758 | G40: 89478.995 | H40: 84622.073 | I40: 76083.379 | J40: 72351.461 | K40: 74040.678 | L40: 71015.196 | M40: 71227.734 | N40: 74169.561 | O40: 77073.144 | P40: 95122.086 | Q40: 100978.44 | R40: 99602.792 | S40: 83704.433 | T40: 79833.909 | U40: 74726.974 | V40: 71267.934 | W40: 69661.387 | X40: 70664.604 | Y40: 69416.51 | Z40: 68440.793 | AA40: 80808.952 | AB40: 95529.232 | AC40: 90869.271 | AD40: 93280.722 | AE40: 89072.372 | AF40: 89058.283 | AG40: 79151.121 | AH40: 71165.826 | AI40: 71834.767 | AJ40: 72113.371 | AK40: 71702.364 | AL40: 69156.121 | AM40: =+SUM(O40:Z40) -> 960493.01 | AN40: =+SUM(AA40:AL40) -> 973742.4 | AO40: =+AN40/AM40-1 -> 0.013794368 | AP40: =+AM40/$AM$40 -> 1 | AQ40: =+AN40/$AN$40 -> 1
A58: Pesticidas (Resto) | B58: 44440 | C58: 44470 | D58: 44501 | E58: 44531 | F58: 44562 | G58: 44593 | H58: 44621 | I58: 44652 | J58: 44682 | K58: 44713 | L58: 44743 | M58: 44774 | N58: 44805 | O58: 44835 | P58: 44866 | Q58: 44896 | R58: 44927 | S58: 44958 | T58: 44986 | U58: 45017 | V58: 45047 | W58: 45078 | X58: 45108 | Y58: 45139 | Z58: 45170 | AA58: 45200 | AB58: 45231 | AC58: 45261 | AD58: 45292 | AE58: 45323 | AF58: 45352 | AG58: 45383 | AH58: 45413 | AI58: 45444 | AJ58: 45474 | AK58: 45505 | AL58: 45536 | AM58: UAM-1 | AN58: UAM | AO58: Var. UAM | AP58: Aporte UAM-1 | AQ58: Aporte UAM
A59: BAYGON | B59: 3727.181 | C59: 3848.599 | D59: 6120.863 | E59: 4922.607 | F59: 3764.487 | G59: 4245.521 | H59: 4252.146 | I59: 4153.134 | J59: 4105.661 | K59: 3829.55 | L59: 3441.641 | M59: 3637.799 | N59: 4331.299 | O59: 5090.092 | P59: 4943.898 | Q59: 4730.071 | R59: 4947.363 | S59: 3806.909 | T59: 3199.512 | U59: 3201.959 | V59: 3726.781 | W59: 4727.261 | X59: 4566.703 | Y59: 4085.997 | Z59: 4389.602 | AA59: 4251.875 | AB59: 5460.255 | AC59: 4800.48 | AD59: 4427.037 | AE59: 5276.825 | AF59: 3694.843 | AG59: 3798.577 | AH59: 3526.922 | AI59: 4074.071 | AJ59: 3490.732 | AK59: 3132.594 | AL59: 3605.118 | AM59: =+SUM(O59:Z59) -> 51416.148 | AN59: =+SUM(AA59:AL59) -> 49539.329 | AO59: =+AN59/AM59-1 -> -0.036502521 | AP59: =+AM59/$AM$62 -> 0.052584386 | AQ59: =+AN59/$AN$62 -> 0.047397899
A60: FUYI | B60: 8778.905 | C60: 10955.553 | D60: 14169.925 | E60: 15494.039 | F60: 17194.012 | G60: 14416.961 | H60: 16662.699 | I60: 14384.027 | J60: 14836.665 | K60: 13530.556 | L60: 13047.748 | M60: 13735.789 | N60: 12810.259 | O60: 14208.68 | P60: 13467.418 | Q60: 11761.018 | R60: 12782.46 | S60: 10449.509 | T60: 10312.202 | U60: 10441.59 | V60: 11468.176 | W60: 10773.946 | X60: 9307.478 | Y60: 9610.528 | Z60: 10071.215 | AA60: 10631.793 | AB60: 10462.29 | AC60: 11890.028 | AD60: 13422.899 | AE60: 14775.041 | AF60: 13408.944 | AG60: 12578.137 | AH60: 12583.065 | AI60: 12014.868 | AJ60: 11927.914 | AK60: 12655.276 | AL60: 10847.029 | AM60: =+SUM(O60:Z60) -> 134654.22 | AN60: =+SUM(AA60:AL60) -> 147197.28 | AO60: =+AN60/AM60-1 -> 0.093150174 | AP60: =+AM60/$AM$62 -> 0.13771373 | AQ60: =+AN60/$AN$62 -> 0.14083441
A61: RAID | B61: 62521.192 | C61: 58793.672 | D61: 63888.206 | E61: 69522.052 | F61: 67210.968 | G61: 65161.31 | H61: 65144.327 | I61: 60075.991 | J61: 56174.837 | K61: 57852.729 | L61: 54867.352 | M61: 55960.181 | N61: 58226.819 | O61: 60164.658 | P61: 73551.681 | Q61: 72076.607 | R61: 73150.009 | S61: 67605.22 | T61: 68471.99 | U61: 63172.393 | V61: 63874.332 | W61: 61104.938 | X61: 62089.015 | Y61: 61254.936 | Z61: 65197.412 | AA61: 70412.591 | AB61: 75981.487 | AC61: 71329.557 | AD61: 74505.323 | AE61: 72842.572 | AF61: 75470.132 | AG61: 71969.05 | AH61: 67640.379 | AI61: 69522.507 | AJ61: 66083.583 | AK61: 65933.898 | AL61: 66752.148 | AM61: =+SUM(O61:Z61) -> 791713.19 | AN61: =+SUM(AA61:AL61) -> 848443.23 | AO61: =+AN61/AM61-1 -> 0.071654782 | AP61: =+AM61/$AM$62 -> 0.80970189 | AQ61: =+AN61/$AN$62 -> 0.81176769
A62: Total general | B62: 75027.278 | C62: 73597.824 | D62: 84178.994 | E62: 89938.698 | F62: 88169.467 | G62: 83823.792 | H62: 86059.172 | I62: 78613.152 | J62: 75117.163 | K62: 75212.835 | L62: 71356.741 | M62: 73333.769 | N62: 75368.377 | O62: 79463.43 | P62: 91962.997 | Q62: 88567.696 | R62: 90879.832 | S62: 81861.638 | T62: 81983.704 | U62: 76815.942 | V62: 79069.289 | W62: 76606.145 | X62: 75963.196 | Y62: 74951.461 | Z62: 79658.229 | AA62: 85296.259 | AB62: 91904.032 | AC62: 88020.065 | AD62: 92355.259 | AE62: 92894.438 | AF62: 92573.919 | AG62: 88345.764 | AH62: 83750.366 | AI62: 85611.446 | AJ62: 81502.229 | AK62: 81721.768 | AL62: 81204.295 | AM62: =+SUM(O62:Z62) -> 977783.56 | AN62: =+SUM(AA62:AL62) -> 1045179.8 | AO62: =+AN62/AM62-1 -> 0.068927607 | AP62: =+AM62/$AM$62 -> 1 | AQ62: =+AN62/$AN$62 -> 1

Sheet Inventario
A1: Markets | B1: PEST CONTROL | C1: MANUFACTURER | D1: CATEGORY | E1: SEGMENT | F1: BRAND | G1: FORM | H1: Facts | I1: Sep 21 - w/e 22/09/21 | J1: Oct 21 - w/e 23/10/21 | K1: Nov 21 - w/e 22/11/21 | L1: Dec 21 - w/e 23/12/21 | M1: Jan 22 - w/e 23/01/22 | N1: Feb 22 - w/e 20/02/22 | O1: Mar 22 - w/e 23/03/22 | P1: Apr 22 - w/e 22/04/22 | Q1: May 22 - w/e 23/05/22 | R1: Jun 22 - w/e 22/06/22 | S1: Jul 22 - w/e 23/07/22 | T1: Aug 22 - w/e 23/08/22 | U1: Sep 22 - w/e 22/09/22 | V1: Oct 22 - w/e 23/10/22 | W1: Nov 22 - w/e 22/11/22 | X1: Dec 22 - w/e 23/12/22 | Y1: Jan 23 - w/e 23/01/23 | Z1: Feb 23 - w/e 20/02/23 | AA1: Mar 23 - w/e 23/03/23 | AB1: Apr 23 - w/e 22/04/23 | AC1: May 23 - w/e 23/05/23 | AD1: Jun 23 - w/e 22/06/23 | AE1: Jul 23 - w/e 23/07/23 | AF1: Aug 23 - w/e 23/08/23 | AG1: Sep 23 - w/e 22/09/23 | AH1: Oct 23 - w/e 23/10/23 | AI1: Nov 23 - w/e 22/11/23 | AJ1: Dec 23 - w/e 23/12/23 | AK1: Jan 24 - w/e 23/01/24 | AL1: Feb 24 - w/e 21/02/24 | AM1: Mar 24 - w/e 23/03/24 | AN1: Apr 24 - w/e 22/04/24 | AO1: May 24 - w/e 23/05/24 | AP1: Jun 24 - w/e 22/06/24 | AQ1: Jul 24 - w/e 23/07/24 | AR1: Aug 24 - w/e 23/08/24 | AS1: Sep 24 - w/e 22/09/24 | AT1: Oct 24 - w/e 23/10/24
A2: T.URUGUAY TRADICIONALES | B2: PEST CONTROL | C2: SC JOHNSON | D2: PERSONAL REPELLENT | E2: MOSQUITO | F2: FUYI | G2: AEROSOL | H2: Stocks Forward Units | I2: 573.602 | J2: 857.904 | K2: 962.351 | L2: 1004.544 | M2: 741.157 | N2: 734.051 | O2: 593.05 | P2: 912.916 | Q2: 577.753 | R2: 592.206 | S2: 620.046 | T2: 609.533 | U2: 619.366 | V2: 561.446 | W2: 672.779 | X2: 568.788 | Y2: 365.411 | Z2: 461.472 | AA2: 621.172 | AB2: 722.848 | AC2: 732.135 | AD2: 731.089 | AE2: 707.328 | AF2: 449.757 | AG2: 372.993 | AH2: 436.267 | AI2: 518.811 | AJ2: 904.92 | AK2: 921.175 | AL2: 896.42 | AM2: 947.105 | AN2: 1255.278 | AO2: 858.303 | AP2: 756.191 | AQ2: 557.429 | AR2: 630.584 | AS2: 437.786 | AT2: 554.751
A3: T.URUGUAY TRADICIONALES | B3: PEST CONTROL | C3: SC JOHNSON | D3: PERSONAL REPELLENT | E3: MOSQUITO | F3: FUYI | G3: LIQUID BOTTLE | H3: Stocks Forward Units | I3: 0 | J3: 0 | K3: 0 | L3: 17.975 | M3: 26.962 | N3: 26.962 | O3: 35.95 | P3: 26.962 | Q3: 9.862 | R3: 9.862 | S3: 0 | T3: 0 | U3: 0 | V3: 0 | W3: 0 | X3: 0 | Y3: 0 | Z3: 0 | AA3: 0 | AB3: 0 | AC3: 0 | AD3: 0 | AE3: 0 | AF3: 0 | AG3: 0 | AH3: 0 | AI3: 0 | AJ3: 0 | AK3: 0 | AL3: 0 | AM3: 0 | AN3: 0 | AO3: 0 | AP3: 0 | AQ3: 0 | AR3: 0 | AS3: 0 | AT3: 0
A4: T.URUGUAY TRADICIONALES | B4: PEST CONTROL | C4: SC JOHNSON | D4: PERSONAL REPELLENT | E4: MOSQUITO | F4: OFF! | G4: AEROSOL | H4: Stocks Forward Units | I4: 3854.853 | J4: 3229.35 | K4: 4388.874 | L4: 5248.407 | M4: 4712.815 | N4: 5946.142 | O4: 6604.242 | P4: 6179.386 | Q4: 6474.059 | R4: 6669.215 | S4: 6205.884 | T4: 6389.05 | U4: 6336.297 | V4: 6479.669 | W4: 6856.986 | X4: 6581.121 | Y4: 6467.907 | Z4: 6947.202 | AA4: 7294.796 | AB4: 7253.777 | AC4: 7013.167 | AD4: 6619.865 | AE4: 7042.035 | AF4: 7458.324 | AG4: 6859.219 | AH4: 7228.819 | AI4: 8775.338 | AJ4: 8838.679 | AK4: 8418.066 | AL4: 7111.091 | AM4: 7368.204 | AN4: 5274.228 | AO4: 4296.757 | AP4: 3899.561 | AQ4: 4169.443 | AR4: 4256.64 | AS4: 3904.517 | AT4: 4966.456
A5: T.URUGUAY TRADICIONALES | B5: PEST CONTROL | C5: SC JOHNSON | D5: PERSONAL REPELLENT | E5: MOSQUITO | F5: OFF! | G5: LIQUID PUMP | H5: Stocks Forward Units | I5: 0 | J5: 0 | K5: 96.039 | L5: 120.495 | M5: 122.162 | N5: 92.299 | O5: 83.563 | P5: 83.563 | Q5: 83.272 | R5: 76.182 | S5: 76.182 | T5: 76.557 | U5: 76.557 | V5: 73.934 | W5: 68.906 | X5: 76.834 | Y5: 78.791 | Z5: 60.09 | AA5: 0 | AB5: 0 | AC5: 0 | AD5: 0 | AE5: 0 | AF5: 0 | AG5: 0 | AH5: 0 | AI5: 0 | AJ5: 0 | AK5: 0 | AL5: 0 | AM5: 0 | AN5: 56.605 | AO5: 69.736 | AP5: 113.609 | AQ5: 137.882 | AR5: 148.636 | AS5: 121.016 | AT5: 103.129
A6: T.URUGUAY TRADICIONALES | B6: PEST CONTROL | C6: SC JOHNSON | D6: PERSONAL REPELLENT | E6: MOSQUITO | F6: OFF! | G6: LOTION BOTTLE | H6: Stocks Forward Units | I6: 11495.722 | J6: 11182.303 | K6: 13183.27 | L6: 13375.584 | M6: 11303.874 | N6: 13107.697 | O6: 10954.445 | P6: 12821.076 | Q6: 11737.145 | R6: 11527.238 | S6: 12293.464 | T6: 12618.182 | U6: 12745.904 | V6: 11761.256 | W6: 13706.698 | X6: 17059.909 | Y6: 17239.966 | Z6: 17694.236 | AA6: 16675.186 | AB6: 14885.082 | AC6: 13517.04 | AD6: 12601.761 | AE6: 11975.822 | AF6: 12711.97 | AG6: 13194.597 | AH6: 15473.093 | AI6: 15946.36 | AJ6: 16192.951 | AK6: 16782.82 | AL6: 15423.059 | AM6: 14702.069 | AN6: 12047.722 | AO6: 11483.67 | AP6: 10292.971 | AQ6: 10330.913 | AR6: 9418.018 | AS6: 9644.578 | AT6: 9694.565
A7: T.URUGUAY TRADICIONALES | B7: PEST CONTROL | C7: SC JOHNSON | D7: CRAWLING INSECT KILLER | E7: ANT & ROACH | F7: BAYGON | G7: AEROSOL | H7: Stocks Forward Units | I7: 55.002 | J7: 879.883 | K7: 829.599 | L7: 712.913 | M7: 378.141 | N7: 166.3 | O7: 221.734 | P7: 332.601 | Q7: 285.962 | R7: 0 | S7: 126.016 | T7: 210.026 | U7: 296.659 | V7: 169.134 | W7: 282.68 | X7: 0 | Y7: 0 | Z7: 0 | AA7: 0 | AB7: 0 | AC7: 0 | AD7: 0 | AE7: 0 | AF7: 0 | AG7: 0 | AH7: 0 | AI7: 0 | AJ7: 34.172 | AK7: 34.172 | AL7: 0 | AM7: 32.382 | AN7: 32.382 | AO7: 0 | AP7: 0 | AQ7: 0 | AR7: 0 | AS7: 0 | AT7: 0
A8: T.URUGUAY TRADICIONALES | B8: PEST CONTROL | C8: SC JOHNSON | D8: CRAWLING INSECT KILLER | E8: ANT & ROACH | F8: BAYGON | G8: BAIT GEL | H8: Stocks Forward Units | I8: 79.767 | J8: 20.367 | K8: 79.832 | L8: 74.928 | M8: 54.761 | N8: 0 | O8: 0 | P8: 0 | Q8: 0 | R8: 0 | S8: 0 | T8: 0 | U8: 0 | V8: 0 | W8: 0 | X8: 0 | Y8: 0 | Z8: 0 | AA8: 0 | AB8: 0 | AC8: 0 | AD8: 0 | AE8: 0 | AF8: 0 | AG8: 0 | AH8: 0 | AI8: 0 | AJ8: 0 | AK8: 0 | AL8: 0 | AM8: 0 | AN8: 0 | AO8: 0 | AP8: 32.431 | AQ8: 32.472 | AR8: 0 | AS8: 28.346 | AT8: 28.831
A9: T.URUGUAY TRADICIONALES | B9: PEST CONTROL | C9: SC JOHNSON | D9: CRAWLING INSECT KILLER | E9: ANT & ROACH | F9: RAID | G9: AEROSOL | H9: Stocks Forward Units | I9: 4297.469 | J9: 4092.798 | K9: 4116.855 | L9: 3104.91 | M9: 3189.788 | N9: 4153.35 | O9: 3834.866 | P9: 3329.882 | Q9: 3190.778 | R9: 3570.102 | S9: 3119.236 | T9: 2961.021 | U9: 3557.388 | V9: 3849.586 | W9: 4348.456 | X9: 3735.401 | Y9: 2993.752 | Z9: 2244.606 | AA9: 2948.521 | AB9: 2486.065 | AC9: 2704.857 | AD9: 2722.226 | AE9: 2571.481 | AF9: 2480.708 | AG9: 3373.879 | AH9: 4714.505 | AI9: 6483.512 | AJ9: 5003.926 | AK9: 5544.596 | AL9: 4304.89 | AM9: 4099.631 | AN9: 4580.466 | AO9: 3970.892 | AP9: 4080.662 | AQ9: 3283.076 | AR9: 3530.679 | AS9: 3498.069 | AT9: 4227.842
A10: T.URUGUAY TRADICIONALES | B10: PEST CONTROL | C10: SC JOHNSON | D10: CRAWLING INSECT KILLER | E10: ANT & ROACH | F10: RAID | G10: BAIT GEL | H10: Stocks Forward Units | I10: 52.086 | J10: 111.071 | K10: 110.372 | L10: 146.048 | M10: 194.082 | N10: 244.464 | O10: 186.868 | P10: 232.526 | Q10: 332.102 | R10: 301.139 | S10: 417.192 | T10: 391.462 | U10: 360.465 | V10: 384.423 | W10: 298.491 | X10: 220.5 | Y10: 205.939 | Z10: 205.939 | AA10: 222.976 | AB10: 223.125 | AC10: 136.661 | AD10: 195.582 | AE10: 157.893 | AF10: 151.073 | AG10: 97.807 | AH10: 169.332 | AI10: 134.382 | AJ10: 134.382 | AK10: 134.034 | AL10: 75.031 | AM10: 234.598 | AN10: 464.833 | AO10: 504.331 | AP10: 468.53 | AQ10: 398.179 | AR10: 396.205 | AS10: 339.665 | AT10: 455.336
