Workbook

Sheet Shipments
A1: Category | B1: Segment | C1: Country | D1: Channel Name | E1: Brand | F1: SKU | G1: Facts | H1: 44621 | I1: 44652 | J1: 44682 | K1: 44713 | L1: 44743 | M1: 44774 | N1: 44805 | O1: 44835 | P1: 44866 | Q1: 44896 | R1: 44927 | S1: 44958 | T1: 44986 | U1: 45017 | V1: 45047 | W1: 45078 | X1: 45108 | Y1: 45139 | Z1: 45170 | AA1: 45200 | AB1: 45231 | AC1: 45261 | AD1: 45292 | AE1: 45323 | AF1: 45352 | AG1: 45383 | AH1: 45413 | AI1: 45444 | AJ1: 45474 | AK1: 45505 | AL1: 45536 | AM1: 45566 | AN1: 45597 | AO1: 45627 | AP1: 45658 | AQ1: 45689 | AR1: 45717 | AS1: 45748
A2: GUARNICIONES | B2: Guarniciones | C2: Argentina | D2: 3PD | E2: 3D's | F2: 3D MEGA QUESO PC DTS 25GRX120 | G2: Sales | P2: 0
A3: GUARNICIONES | B3: Guarniciones | C3: Argentina | D3: 3PD | E3: 3D's | F3: 3D QUESO 143GX18X1 | G3: Sales | O3: 21.164143 | P3: 23.376639 | Q3: 24.700819 | R3: 29.501043 | S3: 20.884578 | T3: 13.971815 | U3: 14.442571 | V3: 15.528656 | W3: 16.670225 | X3: 16.347903 | Y3: 13.139984 | Z3: 16.001986 | AA3: 14.153854 | AB3: 18.114525 | AC3: 16.727997 | AD3: 14.877863 | AE3: 9.085362 | AF3: 6.776055 | AG3: 9.039602 | AH3: 6.030167 | AI3: 17.765891 | AJ3: 14.623466 | AK3: 13.48633 | AL3: 8.316594 | AM3: 0.080938 | AN3: 7.898891 | AO3: 25.153271 | AP3: 18.215769 | AQ3: 16.965806 | AR3: 15.272543 | AS3: 15.82438
A4: GUARNICIONES | B4: Guarniciones | C4: Argentina | D4: 3PD | E4: 3D's | F4: 3D QUESO 165GX20 | G4: Sales
A5: GUARNICIONES | B5: Guarniciones | C5: Argentina | D5: 3PD | E5: 3D's | F5: 3D QUESO 165GX20 PROMO PI | G5: Sales | P5: 0
A6: GUARNICIONES | B6: Guarniciones | C6: Argentina | D6: 3PD | E6: 3D's | F6: 3D QUESO 43GX75X1 | G6: Sales | O6: 41.151 | P6: 36.664208 | Q6: 22.657474 | R6: 27.932929 | S6: 21.634332 | T6: 23.036605 | U6: 29.017776 | V6: 19.17714 | W6: 25.037782 | X6: 24.234069 | Y6: 22.046616 | Z6: 24.734288 | AA6: 21.652392 | AB6: 22.591512 | AC6: 29.768771 | AD6: 13.461408 | AE6: 10.676341 | AF6: 9.705874 | AG6: 14.606627 | AH6: 12.692869 | AI6: 21.195259 | AJ6: 21.776146 | AK6: 18.686639 | AL6: 10.870959 | AM6: 0.205712 | AN6: 12.750747 | AO6: 27.075036 | AP6: 18.64093 | AQ6: 19.483988 | AR6: 19.8402 | AS6: 20.823825
A7: GUARNICIONES | B7: Guarniciones | C7: Argentina | D7: 3PD | E7: 3D's | F7: 3D QUESO 85GX27X1 | G7: Sales | AA7: 0.3672 | AB7: -0.1836 | AE7: 0.00459 | AF7: 18.775395 | AG7: 25.199695 | AH7: 18.519885 | AI7: 43.2565 | AJ7: 44.865125 | AK7: 30.51772 | AL7: 19.66747 | AM7: -0.01938 | AN7: 24.780305 | AO7: 67.15323 | AP7: 47.648025 | AQ7: 40.943565 | AR7: 43.43517 | AS7: 41.690375
A8: GUARNICIONES | B8: Guarniciones | C8: Argentina | D8: 3PD | E8: 3D's | F8: 3D QUESO 92GX27X1 | G8: Sales | O8: 70.154416 | P8: 60.090168 | Q8: 52.040168 | R8: 68.568152 | S8: 50.4367 | T8: 41.998828 | U8: 44.432136 | V8: 30.869036 | W8: 45.05746 | X8: 40.846344 | Y8: 36.691624 | Z8: 40.50668 | AA8: 41.648952 | AB8: 46.298264 | AC8: 49.951492 | AD8: 37.514012 | AE8: 28.477036 | AF8: 1.045304 | AG8: -0.008832 | AH8: -0.068172 | AI8: -9.2e-05 | AJ8: 0 | AK8: -0.000644 | AL8: -9.2e-05 | AN8: -0.000828 | AR8: -0.003404
A9: GUARNICIONES | B9: Guarniciones | C9: Argentina | D9: 3PD | E9: 3D's | F9: 3DMEGAQUESO100GX24 | G9: Sales | J9: 0 | K9: 0 | L9: 0
A10: GUARNICIONES | B10: Guarniciones | C10: Argentina | D10: 3PD | E10: 3D's | F10: 3DMEGAQUESO150GX17 | G10: Sales | I10: 0 | J10: 0 | L10: 0 | Q10: 0 | S10: 0 | U10: 0 | V10: -0.00075
A11: GUARNICIONES | B11: Guarniciones | C11: Argentina | D11: 3PD | E11: 3D's | F11: 3DMEGAQUESO151GX17 | G11: Sales | H11: 31.678894 | I11: 22.672499 | J11: 22.404021 | K11: 25.179099 | L11: 27.827488 | M11: 32.723965 | N11: 22.735466 | O11: 4.778999 | P11: 0.025519 | Q11: -0.004832 | R11: -0.002869 | S11: -0.002265 | T11: -0.002869 | U11: -0.002265 | V11: -0.002265 | W11: -0.001963 | Y11: -0.000151 | AB11: -0.000302 | AC11: -0.002114 | AD11: -0.000453
A12: GUARNICIONES | B12: Guarniciones | C12: Argentina | D12: 3PD | E12: 3D's | F12: 3DMEGAQUESO23GX120 | G12: Sales | H12: 2.269686 | I12: 2.24112 | J12: 2.64132 | K12: 1.45038 | L12: 2.532001 | M12: 3.256547 | N12: 2.185759 | O12: 2.403891 | P12: 2.85384 | Q12: 1.774427 | R12: 1.680127 | S12: 1.6721 | T12: 2.775456 | U12: 1.811135 | V12: 1.736247 | W12: 2.302806 | X12: 2.094886 | Y12: 1.91498 | Z12: 2.595734 | AA12: 1.727438 | AB12: 1.845152 | AC12: 2.511807 | AD12: 0.850494 | AE12: 1.103172 | AF12: 1.333862 | AG12: 1.099032 | AH12: 1.032102 | AI12: 1.269462 | AJ12: 1.474093 | AK12: 1.681737 | AL12: 0.839592 | AM12: -0.003335 | AN12: 1.181993 | AO12: 1.384117 | AP12: 1.06099 | AQ12: 1.392098 | AR12: 1.207914 | AS12: 1.14816
A13: GUARNICIONES | B13: Guarniciones | C13: Argentina | D13: 3PD | E13: 3D's | F13: 3DMEGAQUESO46GX60 | G13: Sales | K13: 0 | L13: 0 | U13: 0
A14: GUARNICIONES | B14: Guarniciones | C14: Argentina | D14: 3PD | E14: 3D's | F14: 3DMEGAQUESO47GX60 | G14: Sales | H14: 44.231324 | I14: 38.507429 | J14: 37.1958 | K14: 33.404921 | L14: 38.415873 | M14: 44.349247 | N14: 30.78641 | O14: 0.080793 | P14: 0.050102 | Q14: -0.005687 | R14: 0 | S14: 0 | U14: -0.000141 | V14: -0.000141 | W14: -0.000329 | AB14: -4.7e-05 | AC14: -4.7e-05 | AD14: -0.000141 | AE14: -0.000141
A15: GUARNICIONES | B15: Guarniciones | C15: Argentina | D15: 3PD | E15: 3D's | F15: 3DMEGAQUESO95GX24 | G15: Sales | H15: 74.62725 | I15: 55.663445 | J15: 57.163305 | K15: 54.496085 | L15: 69.413745 | M15: 71.385755 | N15: 49.769075 | O15: 1.84851 | P15: 0.01045 | Q15: -0.090345 | R15: -0.0019 | S15: 0 | U15: -9.5e-05 | X15: -0.00019 | AB15: -9.5e-05 | AC15: -0.00684 | AD15: -0.00019
A16: GUARNICIONES | B16: Guarniciones | C16: Argentina | D16: 3PD | E16: 3D's | F16: 3DS MEGA QUESO 105GR X 24 | G16: Sales | K16: 0
A17: GUARNICIONES | B17: Guarniciones | C17: Argentina | D17: 3PD | E17: 3D's | F17: 3DS MEGA QUESO 48GRX60 PI | G17: Sales | T17: 0
A18: GUARNICIONES | B18: Guarniciones | C18: Argentina | D18: 3PD | E18: CHEETOS | F18: CHEETOS 150GRX17 | G18: Sales | I18: 0 | K18: 0 | L18: 0 | U18: 0
A19: GUARNICIONES | B19: Guarniciones | C19: Argentina | D19: 3PD | E19: CHEETOS | F19: CHEETOS 151GRX17 | G19: Sales | I19: 0 | J19: 0 | K19: 0 | L19: 0 | M19: 0 | O19: 0.003322 | Q19: 0 | S19: -0.000453 | U19: 0 | V19: -0.002416 | W19: -0.000151
A20: GUARNICIONES | B20: Guarniciones | C20: Argentina | D20: 3PD | E20: CHEETOS | F20: CHEETOS 151GX18 | G20: Sales | H20: 18.840421 | I20: 17.530798 | J20: 16.368098 | K20: 19.812559 | L20: 23.23135 | M20: 23.227726 | N20: 21.403797 | O20: 20.910631 | P20: 20.891001 | Q20: 23.682236 | R20: 20.873787 | S20: 18.931474 | T20: 14.179202 | U20: 11.986682 | V20: 13.646625 | W20: 15.528085 | X20: 15.528236 | Y20: 12.519561 | Z20: 15.292827 | AA20: 15.123405 | AB20: 14.598982 | AC20: 13.820728 | AD20: 0.433823 | AE20: -0.022952 | AF20: -0.005285 | AH20: -0.003624 | AI20: -0.000302 | AN20: -0.000604 | AQ20: -0.000151
A21: GUARNICIONES | B21: Guarniciones | C21: Argentina | D21: 3PD | E21: CHEETOS | F21: CHEETOS 238GRX12 | G21: Sales | H21: 1.414434 | I21: 1.55533 | J21: 1.17572 | K21: 1.27568 | L21: 1.658384 | M21: 1.429666 | N21: 1.51606 | O21: 2.085118 | P21: 1.571752 | Q21: 1.324946 | R21: 1.901382 | S21: 1.34708 | T21: 0.917014 | U21: 1.167152 | V21: 1.331848 | W21: 1.056482 | X21: 1.016736 | Y21: 1.119076 | Z21: 1.044582 | AA21: 1.144542 | AB21: 0.344148 | AC21: 0.79016 | AD21: -0.008092 | AE21: -0.00357 | AF21: -0.049742 | AG21: -0.000238 | AH21: -0.000952 | AN21: -0.000714
A22: GUARNICIONES | B22: Guarniciones | C22: Argentina | D22: 3PD | E22: CHEETOS | F22: CHEETOS 23GRX108 | G22: Sales | H22: 1.748736 | I22: 1.495368 | J22: 1.224612 | K22: 0.881751 | L22: 1.843979 | M22: 1.798416 | N22: 2.354832 | O22: 1.525613 | P22: 1.319004 | Q22: 1.887702 | R22: 1.040727 | S22: 1.578835 | T22: 1.721067 | U22: 2.536854 | V22: 2.184126 | W22: 1.708187 | X22: 1.889933 | Y22: 2.034856 | Z22: 2.124901 | AA22: 2.422728 | AB22: 1.400838 | AC22: 2.245007 | AD22: 0.700097 | AE22: 0.823078 | AF22: 1.558641 | AG22: 0.927751 | AH22: 0.89608 | AI22: 1.277926 | AJ22: 1.765434 | AK22: 1.505695 | AL22: 1.521772 | AM22: 1.822221 | AN22: 0.807875 | AO22: 0.917355 | AP22: 1.222772 | AQ22: 1.402195 | AR22: 1.396284 | AS22: 1.362497
A23: GUARNICIONES | B23: Guarniciones | C23: Argentina | D23: 3PD | E23: CHEETOS | F23: CHEETOS 250GRX12 | G23: Sales | K23: 0
A24: GUARNICIONES | B24: Guarniciones | C24: Argentina | D24: 3PD | E24: CHEETOS | F24: CHEETOS 47GRX66 | G24: Sales | H24: 28.138242 | I24: 25.76822 | J24: 28.733732 | K24: 24.356669 | L24: 26.343265 | M24: 34.418335 | N24: 22.444427 | O24: 34.629835 | P24: 37.969373 | Q24: 26.31342 | R24: 19.894348 | S24: 25.35321 | T24: 28.904906 | U24: 0.611423 | V24: 24.052955 | W24: -0.016779 | X24: -0.000282 | Y24: -0.001222 | Z24: -9.4e-05 | AA24: -0.00188 | AB24: -0.000705 | AC24: -0.020069 | AD24: -0.000893 | AE24: -0.000282
A25: GUARNICIONES | B25: Guarniciones | C25: Argentina | D25: 3PD | E25: CHEETOS | F25: CHEETOS 48GRX66 | G25: Sales | H25: 0 | I25: 0 | K25: 0 | L25: 0
A26: GUARNICIONES | B26: Guarniciones | C26: Argentina | D26: 3PD | E26: CHEETOS | F26: CHEETOS 94GRX24 | G26: Sales | H26: 46.2621 | I26: 39.815674 | J26: 43.712256 | K26: 39.366448 | L26: 56.111608 | M26: 54.80952 | N26: 53.926014 | O26: 47.690806 | P26: 55.041794 | Q26: 54.528648 | R26: 57.345828 | S26: 42.111718 | T26: 39.013008 | U26: 36.373582 | V26: 41.043784 | W26: 40.665246 | X26: 42.352922 | Y26: 33.217626 | Z26: 35.20817 | AA26: 9.930254 | AB26: -0.017672 | AC26: 39.147146 | AD26: -0.0141 | AE26: -0.001598 | AF26: -0.003008 | AG26: -0.000376 | AH26: -0.00282
A27: GUARNICIONES | B27: Guarniciones | C27: Argentina | D27: 3PD | E27: CHEETOS | F27: CHEETOS 95GRX24 | G27: Sales | I27: 0 | K27: 0 | L27: 0 | P27: 0
A28: GUARNICIONES | B28: Guarniciones | C28: Argentina | D28: 3PD | E28: CHEETOS | F28: CHEETOS QUESO 105GR X 24 | G28: Sales | K28: 0
A29: GUARNICIONES | B29: Guarniciones | C29: Argentina | D29: 3PD | E29: CHEETOS | F29: CHEETOS QUESO 105GR X 24 PI | G29: Sales | P29: 0
A30: GUARNICIONES | B30: Guarniciones | C30: Argentina | D30: 3PD | E30: CHEETOS | F30: CHEETOS QUESO 140GX18X1 | G30: Sales | AB30: 0.8316 | AD30: 13.11156 | AE30: 7.84266 | AF30: 6.46814 | AG30: 8.49184 | AH30: 6.32142 | AI30: 12.8653 | AJ30: 16.9134 | AK30: 12.84486 | AL30: 15.92724 | AM30: 19.08802 | AN30: 8.39286 | AO30: 19.63878 | AP30: 15.24866 | AQ30: 13.97032 | AR30: 14.43974 | AS30: 13.3994
A31: GUARNICIONES | B31: Guarniciones | C31: Argentina | D31: 3PD | E31: CHEETOS | F31: CHEETOS QUESO 165GX17 PI | G31: Sales | P31: 0
A32: GUARNICIONES | B32: Guarniciones | C32: Argentina | D32: 3PD | E32: CHEETOS | F32: CHEETOS QUESO 229GX12X1 | G32: Sales | AB32: 0.72822 | AD32: 0.937068 | AE32: 0.834018 | AF32: 0.562882 | AG32: 0.556699 | AH32: 0.288082 | AI32: 0.988593 | AJ32: 0.993631 | AK32: 0.923328 | AL32: 0.925618 | AM32: 1.710859 | AN32: 0.455023 | AO32: 1.143626 | AP32: 0.937297 | AQ32: 1.046759 | AR32: 0.861727 | AS32: 0.959052
A33: GUARNICIONES | B33: Guarniciones | C33: Argentina | D33: 3PD | E33: CHEETOS | F33: CHEETOS QUESO 43GX70X1 | G33: Sales | U33: 23.170464 | W33: 21.698273 | X33: 19.113371 | Y33: 23.019792 | Z33: 21.209965 | AA33: 23.16926 | AB33: 19.981799 | AC33: 22.308357 | AD33: 12.501519 | AE33: 11.843189 | AF33: 9.068786 | AG33: 14.564616 | AH33: 9.079665 | AI33: 11.472357 | AJ33: 24.661317 | AK33: 17.762526 | AL33: 18.723404 | AM33: 20.061306 | AN33: 11.238609 | AO33: 19.832159 | AP33: 17.480274 | AQ33: 18.870722 | AR33: 20.293205 | AS33: 17.881765
A34: GUARNICIONES | B34: Guarniciones | C34: Argentina | D34: 3PD | E34: CHEETOS | F34: CHEETOS QUESO 85GX24X1 | G34: Sales | AA34: 26.1528 | AB34: 40.1472 | AD34: 33.83527 | AE34: 26.125855 | AF34: 18.728645 | AG34: 27.752245 | AH34: 9.1239 | AI34: 26.50419 | AJ34: 43.782225 | AK34: 31.267845 | AL34: 45.93383 | AM34: 50.01366 | AN34: 22.4434 | AO34: 36.30061 | AP34: 50.62889 | AQ34: 37.39796 | AR34: 40.05047 | AS34: 36.743545
A35: GUARNICIONES | B35: Guarniciones | C35: Argentina | D35: 3PD | E35: CHEETOS | F35: CHEETOS QUESO CREMA 43GX66 | G35: Sales | AD35: 0.1419 | AE35: 14.277978 | AF35: 11.72395 | AG35: 5.496518 | AH35: 4.102372 | AI35: 6.375524 | AJ35: 4.415111 | AK35: 5.349243 | AL35: 5.128094 | AM35: 6.388639 | AN35: 3.221173 | AO35: 4.411714 | AP35: 3.512068 | AQ35: 3.348023 | AR35: 3.91128 | AS35: 3.907883
A36: GUARNICIONES | B36: Guarniciones | C36: Argentina | D36: 3PD | E36: CHEETOS | F36: CHEETOS QUESO CREMA 85GX24 | G36: Sales | AD36: 0.1428 | AE36: 22.83576 | AF36: 20.617855 | AG36: 9.44741 | AH36: 9.79676 | AI36: 10.971205 | AJ36: 7.90109 | AK36: 14.919965 | AL36: 9.54856 | AM36: 16.22174 | AN36: 8.57582 | AO36: 15.23217 | AP36: 12.51914 | AQ36: 8.49745 | AR36: 10.06009 | AS36: 12.8112
A37: GUARNICIONES | B37: Guarniciones | C37: Argentina | D37: 3PD | E37: Doritos | F37: DORITOS DINAMITA FH 33GX110X1 | G37: Sales | AI37: 7.15473 | AJ37: 12.94458 | AK37: 14.934612 | AL37: 13.660416 | AM37: 2.48193 | AO37: 10.830171 | AP37: 3.466254 | AQ37: -0.003366 | AR37: -0.005511 | AS37: 0
A38: GUARNICIONES | B38: Guarniciones | C38: Argentina | D38: 3PD | E38: Doritos | F38: DORITOS DINAMITA FH 33GX40X1 EX AR | G38: Sales | W38: 4.34808 | X38: 5.24964 | Y38: 10.831227 | Z38: 10.049061 | AA38: 16.044369 | AB38: 2.711313 | AD38: 12.086712 | AE38: 14.684142 | AF38: 12.341967 | AG38: 10.91046 | AH38: 11.336226 | AI38: 7.350783 | AJ38: -0.018513 | AK38: -0.007062 | AL38: -0.002673 | AM38: -0.00033 | AN38: 6.922311 | AO38: -0.000957 | AP38: -0.00561
A39: GUARNICIONES | B39: Guarniciones | C39: Argentina | D39: 3PD | E39: Doritos | F39: DORITOS DINAMITA FH 45GX110X1 | G39: Sales | AP39: 10.28115 | AQ39: 13.52736 | AR39: 12.622815 | AS39: 13.2561
A40: GUARNICIONES | B40: Guarniciones | C40: Argentina | D40: 3PD | E40: Doritos | F40: DORITOS DINAMITA FH 70GX44X1 | G40: Sales | AI40: 11.23276 | AJ40: 24.51904 | AK40: 39.50219 | AL40: 39.19244 | AM40: 29.14044 | AN40: 0.2464 | AO40: 41.09399 | AP40: 15.32412 | AQ40: -0.02058 | AR40: -0.01253 | AS40: -0.00014
...

Sheet DATA NIQ
F1: 1000
A2: FABRICANTE Y MARCA
A3: Markets | B3: CATEGORIA NIQ | C3: FABRICANTE | D3: MARCA | E3: BRAND | F3: TAMANO | G3: Facts | H3: & | I3: 44682 | J3: 44713 | K3: 44743 | L3: 44774 | M3: 44805 | N3: 44835 | O3: 44866 | P3: 44896 | Q3: 44927 | R3: 44958 | S3: 44986 | T3: 45017 | U3: 45047 | V3: 45078 | W3: 45108 | X3: 45139 | Y3: 45170 | Z3: 45200 | AA3: 45231 | AB3: 45261 | AC3: 45292 | AD3: 45323 | AE3: 45352 | AF3: 45383 | AG3: 45413 | AH3: 45444 | AI3: 45474 | AJ3: 45505 | AK3: 45536 | AL3: 45566 | AM3: 45597 | AN3: 45627 | AO3: 45658 | AP3: 45689 | AQ3: 45717 | AR3: 45748 | AS3: 45778 | AT3: 45809 | AU3: MARCA H
A4: TOTAL ARGENTINA - ING | B4: GUARNICIONES PARA COPETIN | G4: Vtas (KILOS) | H4: =+A4&B4&C4&D4&E4&F4&G4 -> TOTAL ARGENTINA - INGGUARNICIONES PARA COPETINVtas (KILOS) | I4: 3697954.9 | J4: 3788014.8 | K4: 4001225.4 | L4: 3993732.7 | M4: 3878410.1 | N4: 4177020.5 | O4: 4136386.1 | P4: 5072840.4 | Q4: 4958067.8 | R4: 4055589.2 | S4: 4147504.7 | T4: 3811420.7 | U4: 3751045.4 | V4: 3633254.9 | W4: 3864458.2 | X4: 3814374.5 | Y4: 3823921.7 | Z4: 4045524.6 | AA4: 3917786.2 | AB4: 4326697 | AC4: 3918577.8 | AD4: 3251491.2 | AE4: 3207263.8 | AF4: 3070801 | AG4: 3094093.8 | AH4: 3055519 | AI4: 3485256.8 | AJ4: 3243459.8 | AK4: 3187603.5 | AL4: 3480311.8 | AM4: 3412891.9 | AN4: 4192953.1 | AO4: 4197131.1 | AP4: 3645259.7 | AQ4: 3804276.2 | AR4: 3647682.3 | AS4: 3645717.1 | AT4: 3596009.3 | AU4: =IF(D4="","",INDEX([1]DICCIONARIO!$G$21:$H$33,MATCH(D4,[1]DICCIONARIO!$G$21:$G$33,0),2))
A5: TOTAL ARGENTINA - ING | B5: GUARNICIONES PARA COPETIN | G5: Compras (KILOS) | H5: =+A5&B5&C5&D5&E5&F5&G5 -> TOTAL ARGENTINA - INGGUARNICIONES PARA COPETINCompras (KILOS) | I5: 3252770.3 | J5: 3279346.6 | K5: 3447785.6 | L5: 3452733 | M5: 3329232.2 | N5: 3854321.5 | O5: 3636576.7 | P5: 4305550.5 | Q5: 4251691.4 | R5: 3510241.4 | S5: 3673900.5 | T5: 3359912.5 | U5: 3312873.3 | V5: 3089583.3 | W5: 3392029.9 | X5: 3426518.1 | Y5: 3228245.5 | Z5: 3621494.5 | AA5: 3342189.4 | AB5: 3890943.2 | AC5: 3432423 | AD5: 2801119 | AE5: 2852830.9 | AF5: 2644790.5 | AG5: 2687435.4 | AH5: 2636748.3 | AI5: 3047775.3 | AJ5: 2813040.5 | AK5: 2776377.1 | AL5: 2981317.2 | AM5: 2217917.2 | AN5: 2634476.9 | AO5: 2608175.6 | AP5: 2342740.3 | AQ5: 2460138.9 | AR5: 2356158.5 | AS5: 2382510.2 | AT5: 2274446.3 | AU5: =IF(D5="","",INDEX([1]DICCIONARIO!$G$21:$H$33,MATCH(D5,[1]DICCIONARIO!$G$21:$G$33,0),2))
A6: TOTAL ARGENTINA - ING | B6: GUARNICIONES PARA COPETIN | G6: Inventario (KILOS) | H6: =+A6&B6&C6&D6&E6&F6&G6 -> TOTAL ARGENTINA - INGGUARNICIONES PARA COPETINInventario (KILOS) | I6: 1131324.2 | J6: 1162440.6 | K6: 1162155.8 | L6: 1180068.4 | M6: 1171910.9 | N6: 1401366 | O6: 1347577 | P6: 1542807.5 | Q6: 1523076.5 | R6: 1326343 | S6: 1336178.5 | T6: 1302105.2 | U6: 1276699.5 | V6: 1207045.6 | W6: 1250060.7 | X6: 1374566.4 | Y6: 1310090.2 | Z6: 1419800.9 | AA6: 1322463.3 | AB6: 1518555.2 | AC6: 1453898.1 | AD6: 1266381.2 | AE6: 1278340.7 | AF6: 1149579.4 | AG6: 1107108.3 | AH6: 1063848.8 | AI6: 1204782.5 | AJ6: 1177883.4 | AK6: 1159810.4 | AL6: 1208189 | AM6: 1104704.7 | AN6: 1216560.3 | AO6: 1188758.5 | AP6: 1121493.7 | AQ6: 1141058.3 | AR6: 1103635 | AS6: 1101781.6 | AT6: 1070135.4 | AU6: =IF(D6="","",INDEX([1]DICCIONARIO!$G$21:$H$33,MATCH(D6,[1]DICCIONARIO!$G$21:$G$33,0),2))
A7: TOTAL ARGENTINA - ING | B7: GUARNICIONES PARA COPETIN | G7: Vtas Valor | H7: =+A7&B7&C7&D7&E7&F7&G7 -> TOTAL ARGENTINA - INGGUARNICIONES PARA COPETINVtas Valor | I7: 6.857217e+09 | J7: 7.2942388e+09 | K7: 8.1399602e+09 | L7: 8.839884e+09 | M7: 9.0834934e+09 | N7: 1.0459157e+10 | O7: 1.1279175e+10 | P7: 1.4187187e+10 | Q7: 1.5175114e+10 | R7: 1.3721313e+10 | S7: 1.5042675e+10 | T7: 1.4871936e+10 | U7: 1.5691595e+10 | V7: 1.5994427e+10 | W7: 1.8168197e+10 | X7: 2.0212664e+10 | Y7: 2.3473547e+10 | Z7: 2.7827115e+10 | AA7: 2.9497528e+10 | AB7: 3.6403243e+10 | AC7: 4.2887436e+10 | AD7: 4.3801604e+10 | AE7: 4.680528e+10 | AF7: 4.7299643e+10 | AG7: 5.1192224e+10 | AH7: 5.2121392e+10 | AI7: 6.149099e+10 | AJ7: 5.9978725e+10 | AK7: 6.1473032e+10 | AL7: 6.8367416e+10 | AM7: 6.8098515e+10 | AN7: 8.1183336e+10 | AO7: 8.4668859e+10 | AP7: 7.8304904e+10 | AQ7: 8.3399837e+10 | AR7: 8.1770517e+10 | AS7: 8.3558964e+10 | AT7: 8.2370842e+10 | AU7: =IF(D7="","",INDEX([1]DICCIONARIO!$G$21:$H$33,MATCH(D7,[1]DICCIONARIO!$G$21:$G$33,0),2))
A8: TOTAL ARGENTINA - ING | B8: GUARNICIONES PARA COPETIN | G8: Dist. Num. Tiendas Handling (C) | H8: =+A8&B8&C8&D8&E8&F8&G8 -> TOTAL ARGENTINA - INGGUARNICIONES PARA COPETINDist. Num. Tiendas Handling (C) | I8: 86.96 | J8: 87.138 | K8: 84.805 | L8: 86.223 | M8: 86.608 | N8: 87.512 | O8: 87.059 | P8: 87.284 | Q8: 86.818 | R8: 87.075 | S8: 86.738 | T8: 86.852 | U8: 87.29 | V8: 87.757 | W8: 86.916 | X8: 86.284 | Y8: 87.962 | Z8: 87.438 | AA8: 87.234 | AB8: 87.662 | AC8: 87.928 | AD8: 86.628 | AE8: 88.499 | AF8: 87.876 | AG8: 88.186 | AH8: 86.245 | AI8: 85.374 | AJ8: 86.11 | AK8: 86.137 | AL8: 87.291 | AM8: 86.153 | AN8: 87.06 | AO8: 87.46 | AP8: 87.773 | AQ8: 88.175 | AR8: 88.29 | AS8: 88.723 | AT8: 89.459 | AU8: =IF(D8="","",INDEX([1]DICCIONARIO!$G$21:$H$33,MATCH('DATA NIQ'!D8,[1]DICCIONARIO!$G$21:$G$33,0),2))
A9: TOTAL ARGENTINA - ING | B9: GUARNICIONES PARA COPETIN | G9: Dist. Pond. Tiendas Handling | H9: =+A9&B9&C9&D9&E9&F9&G9 -> TOTAL ARGENTINA - INGGUARNICIONES PARA COPETINDist. Pond. Tiendas Handling | I9: 98.346 | J9: 98.395 | K9: 98.201 | L9: 98.405 | M9: 98.54 | N9: 98.746 | O9: 98.8 | P9: 98.828 | Q9: 98.969 | R9: 98.901 | S9: 98.833 | T9: 98.9 | U9: 99.028 | V9: 99.105 | W9: 99.111 | X9: 98.929 | Y9: 98.935 | Z9: 98.843 | AA9: 98.814 | AB9: 99.018 | AC9: 99.103 | AD9: 99.016 | AE9: 98.925 | AF9: 98.815 | AG9: 98.686 | AH9: 98.377 | AI9: 98.227 | AJ9: 98.673 | AK9: 98.719 | AL9: 98.524 | AM9: 98.226 | AN9: 98.406 | AO9: 98.417 | AP9: 98.646 | AQ9: 98.727 | AR9: 98.731 | AS9: 98.633 | AT9: 98.857 | AU9: =IF(D9="","",INDEX([1]DICCIONARIO!$G$21:$H$33,MATCH('DATA NIQ'!D9,[1]DICCIONARIO!$G$21:$G$33,0),2))
A10: TOTAL ARGENTINA - ING | B10: GUARNICIONES PARA COPETIN | G10: Part. de Vtas (KILOS) - Product | H10: =+A10&B10&C10&D10&E10&F10&G10 -> TOTAL ARGENTINA - INGGUARNICIONES PARA COPETINPart. de Vtas (KILOS) - Product | I10: 100 | J10: 100 | K10: 100 | L10: 100 | M10: 100 | N10: 100 | O10: 100 | P10: 100 | Q10: 100 | R10: 100 | S10: 100 | T10: 100 | U10: 100 | V10: 100 | W10: 100 | X10: 100 | Y10: 100 | Z10: 100 | AA10: 100 | AB10: 100 | AC10: 100 | AD10: 100 | AE10: 100 | AF10: 100 | AG10: 100 | AH10: 100 | AI10: 100 | AJ10: 100 | AK10: 100 | AL10: 100 | AM10: 100 | AN10: 100 | AO10: 100 | AP10: 100 | AQ10: 100 | AR10: 100 | AS10: 100 | AT10: 100 | AU10: =IF(D10="","",INDEX([1]DICCIONARIO!$G$21:$H$33,MATCH('DATA NIQ'!D10,[1]DICCIONARIO!$G$21:$G$33,0),2))
A11: TOTAL ARGENTINA - ING | B11: GUARNICIONES PARA COPETIN | G11: Part. de Vtas Valor - Product | H11: =+A11&B11&C11&D11&E11&F11&G11 -> TOTAL ARGENTINA - INGGUARNICIONES PARA COPETINPart. de Vtas Valor - Product | I11: 100 | J11: 100 | K11: 100 | L11: 100 | M11: 100 | N11: 100 | O11: 100 | P11: 100 | Q11: 100 | R11: 100 | S11: 100 | T11: 100 | U11: 100 | V11: 100 | W11: 100 | X11: 100 | Y11: 100 | Z11: 100 | AA11: 100 | AB11: 100 | AC11: 100 | AD11: 100 | AE11: 100 | AF11: 100 | AG11: 100 | AH11: 100 | AI11: 100 | AJ11: 100 | AK11: 100 | AL11: 100 | AM11: 100 | AN11: 100 | AO11: 100 | AP11: 100 | AQ11: 100 | AR11: 100 | AS11: 100 | AT11: 100 | AU11: =IF(D11="","",INDEX([1]DICCIONARIO!$G$21:$H$33,MATCH('DATA NIQ'!D11,[1]DICCIONARIO!$G$21:$G$33,0),2))
A12: TOTAL ARGENTINA - ING | B12: GUARNICIONES PARA COPETIN | C12: PEPSICO | G12: Vtas (KILOS) | H12: =+A12&B12&C12&D12&E12&F12&G12 -> TOTAL ARGENTINA - INGGUARNICIONES PARA COPETINPEPSICOVtas (KILOS) | I12: 1713558.2 | J12: 1717476.7 | K12: 1775738.5 | L12: 1804416.1 | M12: 1744715.2 | N12: 1867465.1 | O12: 1878750.4 | P12: 2121312.3 | Q12: 2172328.3 | R12: 1810974.1 | S12: 1818083.5 | T12: 1672999.5 | U12: 1638091.1 | V12: 1585686.1 | W12: 1584517.7 | X12: 1536794.7 | Y12: 1570141.2 | Z12: 1666287.4 | AA12: 1526284.9 | AB12: 1467385.4 | AC12: 1472591.6 | AD12: 1268639.4 | AE12: 1203315.3 | AF12: 1125990 | AG12: 1093196.2 | AH12: 1020963.4 | AI12: 1143379.4 | AJ12: 1110194.2 | AK12: 1137294 | AL12: 1300977.1 | AM12: 1240818.3 | AN12: 1350627.6 | AO12: 1368636 | AP12: 1305763.9 | AQ12: 1374346.7 | AR12: 1345121.6 | AS12: 1345536.5 | AT12: 1282862.2 | AU12: =IF(D12="","",INDEX([1]DICCIONARIO!$G$21:$H$33,MATCH(D12,[1]DICCIONARIO!$G$21:$G$33,0),2))
A13: TOTAL ARGENTINA - ING | B13: GUARNICIONES PARA COPETIN | C13: PEPSICO | G13: Compras (KILOS) | H13: =+A13&B13&C13&D13&E13&F13&G13 -> TOTAL ARGENTINA - INGGUARNICIONES PARA COPETINPEPSICOCompras (KILOS) | I13: 1550047.2 | J13: 1550462.1 | K13: 1598945.9 | L13: 1619562.3 | M13: 1531015.6 | N13: 1768605.2 | O13: 1676019.5 | P13: 1945587.3 | Q13: 1926722.2 | R13: 1586821.7 | S13: 1665736.5 | T13: 1547759.2 | U13: 1469045 | V13: 1398201.4 | W13: 1421582.1 | X13: 1422978.6 | Y13: 1340424.9 | Z13: 1539354.9 | AA13: 1349254 | AB13: 1379788.7 | AC13: 1398102 | AD13: 1135807.4 | AE13: 1114324.6 | AF13: 989263.29 | AG13: 966693.17 | AH13: 941522 | AI13: 1079093.8 | AJ13: 1036318.2 | AK13: 1056907.6 | AL13: 1171746.8 | AM13: 911656.78 | AN13: 1034773.1 | AO13: 1048168.3 | AP13: 960568.01 | AQ13: 1017812.8 | AR13: 977025.66 | AS13: 1001057.5 | AT13: 955215.03 | AU13: =IF(D13="","",INDEX([1]DICCIONARIO!$G$21:$H$33,MATCH(D13,[1]DICCIONARIO!$G$21:$G$33,0),2))
A14: TOTAL ARGENTINA - ING | B14: GUARNICIONES PARA COPETIN | C14: PEPSICO | G14: Inventario (KILOS) | H14: =+A14&B14&C14&D14&E14&F14&G14 -> TOTAL ARGENTINA - INGGUARNICIONES PARA COPETINPEPSICOInventario (KILOS) | I14: 529435.11 | J14: 545084.89 | K14: 542348.58 | L14: 555390.47 | M14: 544816.56 | N14: 647412.16 | O14: 592372.41 | P14: 693003.08 | Q14: 670649.24 | R14: 580607.63 | S14: 585183.98 | T14: 602432.84 | U14: 578422.38 | V14: 566431.16 | W14: 545064.03 | X14: 585818.7 | Y14: 555823.21 | Z14: 611667.88 | AA14: 563927.32 | AB14: 579000.06 | AC14: 606498.44 | AD14: 559281.71 | AE14: 557904.1 | AF14: 519864.15 | AG14: 462769.29 | AH14: 430387.26 | AI14: 467638.24 | AJ14: 473745.96 | AK14: 477565.14 | AL14: 507117 | AM14: 459061.26 | AN14: 469591.54 | AO14: 481350.61 | AP14: 463848.8 | AQ14: 477400.55 | AR14: 456355.91 | AS14: 454878.74 | AT14: 426095.73 | AU14: =IF(D14="","",INDEX([1]DICCIONARIO!$G$21:$H$33,MATCH(D14,[1]DICCIONARIO!$G$21:$G$33,0),2))
A15: TOTAL ARGENTINA - ING | B15: GUARNICIONES PARA COPETIN | C15: PEPSICO | G15: Vtas Valor | H15: =+A15&B15&C15&D15&E15&F15&G15 -> TOTAL ARGENTINA - INGGUARNICIONES PARA COPETINPEPSICOVtas Valor | I15: 4.056743e+09 | J15: 4.2728923e+09 | K15: 4.7044886e+09 | L15: 5.1698565e+09 | M15: 5.3245122e+09 | N15: 6.127727e+09 | O15: 6.7095773e+09 | P15: 8.1870665e+09 | Q15: 9.039762e+09 | R15: 8.2997668e+09 | S15: 9.0052477e+09 | T15: 8.7583797e+09 | U15: 9.2268125e+09 | V15: 9.3680311e+09 | W15: 1.0135654e+10 | X15: 1.1378784e+10 | Y15: 1.3275648e+10 | Z15: 1.5735545e+10 | AA15: 1.5960078e+10 | AB15: 1.8258111e+10 | AC15: 2.2805406e+10 | AD15: 2.389581e+10 | AE15: 2.558695e+10 | AF15: 2.5203153e+10 | AG15: 2.6626742e+10 | AH15: 2.5993333e+10 | AI15: 3.0102304e+10 | AJ15: 3.0126947e+10 | AK15: 3.1294204e+10 | AL15: 3.5807976e+10 | AM15: 3.4458122e+10 | AN15: 3.7518662e+10 | AO15: 3.9207972e+10 | AP15: 3.8118653e+10 | AQ15: 4.0614171e+10 | AR15: 4.0476078e+10 | AS15: 4.1061884e+10 | AT15: 3.9855246e+10 | AU15: =IF(D15="","",INDEX([1]DICCIONARIO!$G$21:$H$33,MATCH(D15,[1]DICCIONARIO!$G$21:$G$33,0),2))
A16: TOTAL ARGENTINA - ING | B16: GUARNICIONES PARA COPETIN | C16: PEPSICO | G16: Dist. Num. Tiendas Handling (C) | H16: =+A16&B16&C16&D16&E16&F16&G16 -> TOTAL ARGENTINA - INGGUARNICIONES PARA COPETINPEPSICODist. Num. Tiendas Handling (C) | I16: 72.018 | J16: 72.182 | K16: 71.16 | L16: 71.127 | M16: 71.372 | N16: 71.384 | O16: 71.184 | P16: 70.764 | Q16: 70.179 | R16: 70.434 | S16: 70.069 | T16: 69.499 | U16: 70.988 | V16: 71.039 | W16: 70.209 | X16: 70.105 | Y16: 68.995 | Z16: 68.558 | AA16: 68.399 | AB16: 68.06 | AC16: 67.368 | AD16: 67.255 | AE16: 66.694 | AF16: 66.336 | AG16: 67.791 | AH16: 67.832 | AI16: 66.564 | AJ16: 67.948 | AK16: 67.961 | AL16: 70.039 | AM16: 69.841 | AN16: 70.306 | AO16: 69.376 | AP16: 68.837 | AQ16: 68.977 | AR16: 68.145 | AS16: 70.145 | AT16: 69.409 | AU16: =IF(D16="","",INDEX([1]DICCIONARIO!$G$21:$H$33,MATCH('DATA NIQ'!D16,[1]DICCIONARIO!$G$21:$G$33,0),2))
A17: TOTAL ARGENTINA - ING | B17: GUARNICIONES PARA COPETIN | C17: PEPSICO | G17: Dist. Pond. Tiendas Handling | H17: =+A17&B17&C17&D17&E17&F17&G17 -> TOTAL ARGENTINA - INGGUARNICIONES PARA COPETINPEPSICODist. Pond. Tiendas Handling | I17: 92.339 | J17: 92.317 | K17: 92.376 | L17: 91.885 | M17: 92.055 | N17: 91.519 | O17: 93.354 | P17: 94.12 | Q17: 93.77 | R17: 93.443 | S17: 93.017 | T17: 93.159 | U17: 93.986 | V17: 93.707 | W17: 93.366 | X17: 93.379 | Y17: 92.244 | Z17: 90.92 | AA17: 90.791 | AB17: 90.806 | AC17: 89.973 | AD17: 92.598 | AE17: 92.187 | AF17: 92.318 | AG17: 92.154 | AH17: 91.709 | AI17: 90.687 | AJ17: 91.352 | AK17: 91.312 | AL17: 91.79 | AM17: 91.915 | AN17: 92.506 | AO17: 92.466 | AP17: 92.776 | AQ17: 93.012 | AR17: 92.914 | AS17: 93.002 | AT17: 92.496 | AU17: =IF(D17="","",INDEX([1]DICCIONARIO!$G$21:$H$33,MATCH('DATA NIQ'!D17,[1]DICCIONARIO!$G$21:$G$33,0),2))
A18: TOTAL ARGENTINA - ING | B18: GUARNICIONES PARA COPETIN | C18: PEPSICO | G18: Part. de Vtas (KILOS) - Product | H18: =+A18&B18&C18&D18&E18&F18&G18 -> TOTAL ARGENTINA - INGGUARNICIONES PARA COPETINPEPSICOPart. de Vtas (KILOS) - Product | I18: 46.338 | J18: 45.34 | K18: 44.38 | L18: 45.181 | M18: 44.985 | N18: 44.708 | O18: 45.42 | P18: 41.817 | Q18: 43.814 | R18: 44.654 | S18: 43.836 | T18: 43.894 | U18: 43.67 | V18: 43.644 | W18: 41.002 | X18: 40.29 | Y18: 41.061 | Z18: 41.188 | AA18: 38.958 | AB18: 33.915 | AC18: 37.58 | AD18: 39.017 | AE18: 37.518 | AF18: 36.668 | AG18: 35.332 | AH18: 33.414 | AI18: 32.806 | AJ18: 34.229 | AK18: 35.679 | AL18: 37.381 | AM18: 36.357 | AN18: 32.212 | AO18: 32.609 | AP18: 35.821 | AQ18: 36.126 | AR18: 36.876 | AS18: 36.907 | AT18: 35.675 | AU18: =IF(D18="","",INDEX([1]DICCIONARIO!$G$21:$H$33,MATCH('DATA NIQ'!D18,[1]DICCIONARIO!$G$21:$G$33,0),2))
A19: TOTAL ARGENTINA - ING | B19: GUARNICIONES PARA COPETIN | C19: PEPSICO | G19: Part. de Vtas Valor - Product | H19: =+A19&B19&C19&D19&E19&F19&G19 -> TOTAL ARGENTINA - INGGUARNICIONES PARA COPETINPEPSICOPart. de Vtas Valor - Product | I19: 59.16 | J19: 58.579 | K19: 57.795 | L19: 58.483 | M19: 58.617 | N19: 58.587 | O19: 59.486 | P19: 57.708 | Q19: 59.57 | R19: 60.488 | S19: 59.865 | T19: 58.892 | U19: 58.801 | V19: 58.571 | W19: 55.788 | X19: 56.295 | Y19: 56.556 | Z19: 56.547 | AA19: 54.106 | AB19: 50.155 | AC19: 53.175 | AD19: 54.555 | AE19: 54.667 | AF19: 53.284 | AG19: 52.013 | AH19: 49.871 | AI19: 48.954 | AJ19: 50.229 | AK19: 50.907 | AL19: 52.376 | AM19: 50.6 | AN19: 46.215 | AO19: 46.307 | AP19: 48.68 | AQ19: 48.698 | AR19: 49.5 | AS19: 49.141 | AT19: 48.385 | AU19: =IF(D19="","",INDEX([1]DICCIONARIO!$G$21:$H$33,MATCH('DATA NIQ'!D19,[1]DICCIONARIO!$G$21:$G$33,0),2))
A20: TOTAL ARGENTINA - ING | B20: GUARNICIONES PARA COPETIN | C20: PEPSICO | D20: 3D | G20: Vtas (KILOS) | H20: =+A20&B20&C20&D20&E20&F20&G20 -> TOTAL ARGENTINA - INGGUARNICIONES PARA COPETINPEPSICO3DVtas (KILOS) | I20: 178393.52 | J20: 179710.14 | K20: 176310.76 | L20: 177353.49 | M20: 173835.91 | N20: 181566.29 | O20: 180118.15 | P20: 200119.17 | Q20: 213825.3 | R20: 180353.99 | S20: 180401.45 | T20: 150993.13 | U20: 139875.03 | V20: 130103.13 | W20: 148967.74 | X20: 141444.39 | Y20: 145722.2 | Z20: 152649.65 | AA20: 128058.46 | AB20: 115318.83 | AC20: 126074.56 | AD20: 102869.53 | AE20: 97748.685 | AF20: 90034.707 | AG20: 87817.31 | AH20: 76489.007 | AI20: 86627.277 | AJ20: 87942.905 | AK20: 97955.569 | AL20: 104284.68 | AM20: 86961.328 | AN20: 61370.434 | AO20: 85749.333 | AP20: 102667.31 | AQ20: 110030.54 | AR20: 112524.57 | AS20: 112164.02 | AT20: 101970.55 | AU20: =IF(D20="","",INDEX([1]DICCIONARIO!$G$21:$H$33,MATCH(D20,[1]DICCIONARIO!$G$21:$G$33,0),2)) -> 3D
A21: TOTAL ARGENTINA - ING | B21: GUARNICIONES PARA COPETIN | C21: PEPSICO | D21: 3D | G21: Compras (KILOS) | H21: =+A21&B21&C21&D21&E21&F21&G21 -> TOTAL ARGENTINA - INGGUARNICIONES PARA COPETINPEPSICO3DCompras (KILOS) | I21: 168050.4 | J21: 168188.52 | K21: 167705.65 | L21: 164682.89 | M21: 158699.93 | N21: 182405.85 | O21: 176759.52 | P21: 199693.95 | Q21: 208162.89 | R21: 159935.29 | S21: 171876.93 | T21: 146046.35 | U21: 132597.04 | V21: 123925.94 | W21: 135012.77 | X21: 130267.82 | Y21: 120804.78 | Z21: 147446.02 | AA21: 114398.27 | AB21: 115558.07 | AC21: 118353.37 | AD21: 91353.535 | AE21: 97544.516 | AF21: 80169.006 | AG21: 80463.883 | AH21: 75653.281 | AI21: 83923.112 | AJ21: 85285.096 | AK21: 95686.013 | AL21: 94086.381 | AM21: 72726.477 | AN21: 49098.514 | AO21: 92701.29 | AP21: 90952.306 | AQ21: 91421.475 | AR21: 91296.506 | AS21: 91318.637 | AT21: 85077.393 | AU21: =IF(D21="","",INDEX([1]DICCIONARIO!$G$21:$H$33,MATCH(D21,[1]DICCIONARIO!$G$21:$G$33,0),2)) -> 3D
A22: TOTAL ARGENTINA - ING | B22: GUARNICIONES PARA COPETIN | C22: PEPSICO | D22: 3D | G22: Inventario (KILOS) | H22: =+A22&B22&C22&D22&E22&F22&G22 -> TOTAL ARGENTINA - INGGUARNICIONES PARA COPETINPEPSICO3DInventario (KILOS) | I22: 59749.283 | J22: 59407.737 | K22: 61286.882 | L22: 62016.083 | M22: 61954.278 | N22: 73106.26 | O22: 72426.224 | P22: 78259.449 | Q22: 77125.209 | R22: 62686.508 | S22: 63129.05 | T22: 65805.001 | U22: 61032.788 | V22: 60231.177 | W22: 58232.671 | X22: 62173.28 | Y22: 57811.17 | Z22: 65317.38 | AA22: 55039.356 | AB22: 56994.099 | AC22: 53677.977 | AD22: 47140.375 | AE22: 50956.281 | AF22: 44541.85 | AG22: 40150.836 | AH22: 37883.527 | AI22: 39138.629 | AJ22: 41667.749 | AK22: 46077.146 | AL22: 45063.423 | AM22: 37606.775 | AN22: 23383.048 | AO22: 37482.956 | AP22: 44997.565 | AQ22: 47321.412 | AR22: 45472.617 | AS22: 42279.032 | AT22: 40175.124 | AU22: =IF(D22="","",INDEX([1]DICCIONARIO!$G$21:$H$33,MATCH(D22,[1]DICCIONARIO!$G$21:$G$33,0),2)) -> 3D
A23: TOTAL ARGENTINA - ING | B23: GUARNICIONES PARA COPETIN | C23: PEPSICO | D23: 3D | G23: Vtas Valor | H23: =+A23&B23&C23&D23&E23&F23&G23 -> TOTAL ARGENTINA - INGGUARNICIONES PARA COPETINPEPSICO3DVtas Valor | I23: 4.6342114e+08 | J23: 4.9438285e+08 | K23: 5.2023217e+08 | L23: 5.603103e+08 | M23: 5.8375661e+08 | N23: 6.6215734e+08 | O23: 7.1849023e+08 | P23: 8.6222036e+08 | Q23: 1.0082871e+09 | R23: 9.2582265e+08 | S23: 9.9059509e+08 | T23: 8.8633883e+08 | U23: 9.0492596e+08 | V23: 8.9382457e+08 | W23: 1.0642794e+09 | X23: 1.150217e+09 | Y23: 1.3226441e+09 | Z23: 1.5493275e+09 | AA23: 1.5224482e+09 | AB23: 1.665638e+09 | AC23: 2.1276606e+09 | AD23: 2.11024e+09 | AE23: 2.2626065e+09 | AF23: 2.2039588e+09 | AG23: 2.3509743e+09 | AH23: 2.170105e+09 | AI23: 2.4901818e+09 | AJ23: 2.6032285e+09 | AK23: 2.9039604e+09 | AL23: 3.1789535e+09 | AM23: 2.6932236e+09 | AN23: 1.9589668e+09 | AO23: 2.7632024e+09 | AP23: 3.2826538e+09 | AQ23: 3.6182288e+09 | AR23: 3.750119e+09 | AS23: 3.828493e+09 | AT23: 3.5234963e+09 | AU23: =IF(D23="","",INDEX([1]DICCIONARIO!$G$21:$H$33,MATCH(D23,[1]DICCIONARIO!$G$21:$G$33,0),2)) -> 3D
A24: TOTAL ARGENTINA - ING | B24: GUARNICIONES PARA COPETIN | C24: PEPSICO | D24: 3D | G24: Dist. Num. Tiendas Handling (C) | H24: =+A24&B24&C24&D24&E24&F24&G24 -> TOTAL ARGENTINA - INGGUARNICIONES PARA COPETINPEPSICO3DDist. Num. Tiendas Handling (C) | I24: 56.56 | J24: 55.784 | K24: 55.584 | L24: 58.631 | M24: 61.198 | N24: 59.049 | O24: 58.465 | P24: 58.268 | Q24: 56.288 | R24: 54.722 | S24: 56.552 | T24: 55.969 | U24: 57.282 | V24: 57.333 | W24: 55.921 | X24: 55.942 | Y24: 55.327 | Z24: 55.326 | AA24: 53.978 | AB24: 53.969 | AC24: 54.047 | AD24: 51.077 | AE24: 48.944 | AF24: 50.336 | AG24: 50.605 | AH24: 47.63 | AI24: 46.095 | AJ24: 47.537 | AK24: 51.556 | AL24: 52.526 | AM24: 52.904 | AN24: 45.622 | AO24: 48.602 | AP24: 50.847 | AQ24: 53.682 | AR24: 53.488 | AS24: 56.289 | AT24: 54.028 | AU24: =IF(D24="","",INDEX([1]DICCIONARIO!$G$21:$H$33,MATCH('DATA NIQ'!D24,[1]DICCIONARIO!$G$21:$G$33,0),2)) -> 3D
A25: TOTAL ARGENTINA - ING | B25: GUARNICIONES PARA COPETIN | C25: PEPSICO | D25: 3D | G25: Dist. Pond. Tiendas Handling | H25: =+A25&B25&C25&D25&E25&F25&G25 -> TOTAL ARGENTINA - INGGUARNICIONES PARA COPETINPEPSICO3DDist. Pond. Tiendas Handling | I25: 85.016 | J25: 84.848 | K25: 85.571 | L25: 85.855 | M25: 87.187 | N25: 85.965 | O25: 85.616 | P25: 86.63 | Q25: 85.934 | R25: 84.955 | S25: 84.885 | T25: 84.079 | U25: 81.726 | V25: 81.945 | W25: 83.082 | X25: 83.65 | Y25: 84.467 | Z25: 83.627 | AA25: 81.805 | AB25: 81.496 | AC25: 82.408 | AD25: 83.865 | AE25: 83.531 | AF25: 84.03 | AG25: 81.511 | AH25: 76.993 | AI25: 80.082 | AJ25: 81.21 | AK25: 83.115 | AL25: 83.242 | AM25: 81.974 | AN25: 68.65 | AO25: 78.946 | AP25: 82.697 | AQ25: 84.189 | AR25: 85.025 | AS25: 86.202 | AT25: 84.047 | AU25: =IF(D25="","",INDEX([1]DICCIONARIO!$G$21:$H$33,MATCH('DATA NIQ'!D25,[1]DICCIONARIO!$G$21:$G$33,0),2)) -> 3D
A26: TOTAL ARGENTINA - ING | B26: GUARNICIONES PARA COPETIN | C26: PEPSICO | D26: 3D | G26: Part. de Vtas (KILOS) - Product | H26: =+A26&B26&C26&D26&E26&F26&G26 -> TOTAL ARGENTINA - INGGUARNICIONES PARA COPETINPEPSICO3DPart. de Vtas (KILOS) - Product | I26: 4.824 | J26: 4.744 | K26: 4.406 | L26: 4.441 | M26: 4.482 | N26: 4.347 | O26: 4.354 | P26: 3.945 | Q26: 4.313 | R26: 4.447 | S26: 4.35 | T26: 3.962 | U26: 3.729 | V26: 3.581 | W26: 3.855 | X26: 3.708 | Y26: 3.811 | Z26: 3.773 | AA26: 3.269 | AB26: 2.665 | AC26: 3.217 | AD26: 3.164 | AE26: 3.048 | AF26: 2.932 | AG26: 2.838 | AH26: 2.503 | AI26: 2.486 | AJ26: 2.711 | AK26: 3.073 | AL26: 2.996 | AM26: 2.548 | AN26: 1.464 | AO26: 2.043 | AP26: 2.817 | AQ26: 2.892 | AR26: 3.085 | AS26: 3.077 | AT26: 2.836 | AU26: =IF(D26="","",INDEX([1]DICCIONARIO!$G$21:$H$33,MATCH('DATA NIQ'!D26,[1]DICCIONARIO!$G$21:$G$33,0),2)) -> 3D
A27: TOTAL ARGENTINA - ING | B27: GUARNICIONES PARA COPETIN | C27: PEPSICO | D27: 3D | G27: Part. de Vtas Valor - Product | H27: =+A27&B27&C27&D27&E27&F27&G27 -> TOTAL ARGENTINA - INGGUARNICIONES PARA COPETINPEPSICO3DPart. de Vtas Valor - Product | I27: 6.758 | J27: 6.778 | K27: 6.391 | L27: 6.338 | M27: 6.427 | N27: 6.331 | O27: 6.37 | P27: 6.077 | Q27: 6.644 | R27: 6.747 | S27: 6.585 | T27: 5.96 | U27: 5.767 | V27: 5.588 | W27: 5.858 | X27: 5.691 | Y27: 5.635 | Z27: 5.568 | AA27: 5.161 | AB27: 4.575 | AC27: 4.961 | AD27: 4.818 | AE27: 4.834 | AF27: 4.66 | AG27: 4.592 | AH27: 4.164 | AI27: 4.05 | AJ27: 4.34 | AK27: 4.724 | AL27: 4.65 | AM27: 3.955 | AN27: 2.413 | AO27: 3.264 | AP27: 4.192 | AQ27: 4.338 | AR27: 4.586 | AS27: 4.582 | AT27: 4.278 | AU27: =IF(D27="","",INDEX([1]DICCIONARIO!$G$21:$H$33,MATCH('DATA NIQ'!D27,[1]DICCIONARIO!$G$21:$G$33,0),2)) -> 3D
A28: TOTAL ARGENTINA - ING | B28: GUARNICIONES PARA COPETIN | C28: PEPSICO | D28: 3D | E28: 3D | G28: Vtas (KILOS) | H28: =+A28&B28&C28&D28&E28&F28&G28 -> TOTAL ARGENTINA - INGGUARNICIONES PARA COPETINPEPSICO3D3DVtas (KILOS) | I28: 178393.52 | J28: 179710.14 | K28: 176310.76 | L28: 177353.49 | M28: 173835.91 | N28: 181566.29 | O28: 180118.15 | P28: 200119.17 | Q28: 213825.3 | R28: 180353.99 | S28: 180401.45 | T28: 150993.13 | U28: 139875.03 | V28: 130103.13 | W28: 148967.74 | X28: 141444.39 | Y28: 145722.2 | Z28: 152649.65 | AA28: 128058.46 | AB28: 115318.83 | AC28: 126074.56 | AD28: 102869.53 | AE28: 97748.685 | AF28: 90034.707 | AG28: 87817.31 | AH28: 76489.007 | AI28: 86627.277 | AJ28: 87942.905 | AK28: 97955.569 | AL28: 104284.68 | AM28: 86961.328 | AN28: 61370.434 | AO28: 85749.333 | AP28: 102667.31 | AQ28: 110030.54 | AR28: 112524.57 | AS28: 112164.02 | AT28: 101970.55 | AU28: =IF(D28="","",INDEX([1]DICCIONARIO!$G$21:$H$33,MATCH(D28,[1]DICCIONARIO!$G$21:$G$33,0),2)) -> 3D
A29: TOTAL ARGENTINA - ING | B29: GUARNICIONES PARA COPETIN | C29: PEPSICO | D29: 3D | E29: 3D | G29: Compras (KILOS) | H29: =+A29&B29&C29&D29&E29&F29&G29 -> TOTAL ARGENTINA - INGGUARNICIONES PARA COPETINPEPSICO3D3DCompras (KILOS) | I29: 168050.4 | J29: 168188.52 | K29: 167705.65 | L29: 164682.89 | M29: 158699.93 | N29: 182405.85 | O29: 176759.52 | P29: 199693.95 | Q29: 208162.89 | R29: 159935.29 | S29: 171876.93 | T29: 146046.35 | U29: 132597.04 | V29: 123925.94 | W29: 135012.77 | X29: 130267.82 | Y29: 120804.78 | Z29: 147446.02 | AA29: 114398.27 | AB29: 115558.07 | AC29: 118353.37 | AD29: 91353.535 | AE29: 97544.516 | AF29: 80169.006 | AG29: 80463.883 | AH29: 75653.281 | AI29: 83923.112 | AJ29: 85285.096 | AK29: 95686.013 | AL29: 94086.381 | AM29: 72726.477 | AN29: 49098.514 | AO29: 92701.29 | AP29: 90952.306 | AQ29: 91421.475 | AR29: 91296.506 | AS29: 91318.637 | AT29: 85077.393 | AU29: =IF(D29="","",INDEX([1]DICCIONARIO!$G$21:$H$33,MATCH(D29,[1]DICCIONARIO!$G$21:$G$33,0),2)) -> 3D
A30: TOTAL ARGENTINA - ING | B30: GUARNICIONES PARA COPETIN | C30: PEPSICO | D30: 3D | E30: 3D | G30: Inventario (KILOS) | H30: =+A30&B30&C30&D30&E30&F30&G30 -> TOTAL ARGENTINA - INGGUARNICIONES PARA COPETINPEPSICO3D3DInventario (KILOS) | I30: 59749.283 | J30: 59407.737 | K30: 61286.882 | L30: 62016.083 | M30: 61954.278 | N30: 73106.26 | O30: 72426.224 | P30: 78259.449 | Q30: 77125.209 | R30: 62686.508 | S30: 63129.05 | T30: 65805.001 | U30: 61032.788 | V30: 60231.177 | W30: 58232.671 | X30: 62173.28 | Y30: 57811.17 | Z30: 65317.38 | AA30: 55039.356 | AB30: 56994.099 | AC30: 53677.977 | AD30: 47140.375 | AE30: 50956.281 | AF30: 44541.85 | AG30: 40150.836 | AH30: 37883.527 | AI30: 39138.629 | AJ30: 41667.749 | AK30: 46077.146 | AL30: 45063.423 | AM30: 37606.775 | AN30: 23383.048 | AO30: 37482.956 | AP30: 44997.565 | AQ30: 47321.412 | AR30: 45472.617 | AS30: 42279.032 | AT30: 40175.124 | AU30: =IF(D30="","",INDEX([1]DICCIONARIO!$G$21:$H$33,MATCH(D30,[1]DICCIONARIO!$G$21:$G$33,0),2)) -> 3D
A31: TOTAL ARGENTINA - ING | B31: GUARNICIONES PARA COPETIN | C31: PEPSICO | D31: 3D | E31: 3D | G31: Vtas Valor | H31: =+A31&B31&C31&D31&E31&F31&G31 -> TOTAL ARGENTINA - INGGUARNICIONES PARA COPETINPEPSICO3D3DVtas Valor | I31: 4.6342114e+08 | J31: 4.9438285e+08 | K31: 5.2023217e+08 | L31: 5.603103e+08 | M31: 5.8375661e+08 | N31: 6.6215734e+08 | O31: 7.1849023e+08 | P31: 8.6222036e+08 | Q31: 1.0082871e+09 | R31: 9.2582265e+08 | S31: 9.9059509e+08 | T31: 8.8633883e+08 | U31: 9.0492596e+08 | V31: 8.9382457e+08 | W31: 1.0642794e+09 | X31: 1.150217e+09 | Y31: 1.3226441e+09 | Z31: 1.5493275e+09 | AA31: 1.5224482e+09 | AB31: 1.665638e+09 | AC31: 2.1276606e+09 | AD31: 2.11024e+09 | AE31: 2.2626065e+09 | AF31: 2.2039588e+09 | AG31: 2.3509743e+09 | AH31: 2.170105e+09 | AI31: 2.4901818e+09 | AJ31: 2.6032285e+09 | AK31: 2.9039604e+09 | AL31: 3.1789535e+09 | AM31: 2.6932236e+09 | AN31: 1.9589668e+09 | AO31: 2.7632024e+09 | AP31: 3.2826538e+09 | AQ31: 3.6182288e+09 | AR31: 3.750119e+09 | AS31: 3.828493e+09 | AT31: 3.5234963e+09 | AU31: =IF(D31="","",INDEX([1]DICCIONARIO!$G$21:$H$33,MATCH(D31,[1]DICCIONARIO!$G$21:$G$33,0),2)) -> 3D
A32: TOTAL ARGENTINA - ING | B32: GUARNICIONES PARA COPETIN | C32: PEPSICO | D32: 3D | E32: 3D | G32: Dist. Num. Tiendas Handling (C) | H32: =+A32&B32&C32&D32&E32&F32&G32 -> TOTAL ARGENTINA - INGGUARNICIONES PARA COPETINPEPSICO3D3DDist. Num. Tiendas Handling (C) | I32: 56.56 | J32: 55.784 | K32: 55.584 | L32: 58.631 | M32: 61.198 | N32: 59.049 | O32: 58.465 | P32: 58.268 | Q32: 56.288 | R32: 54.722 | S32: 56.552 | T32: 55.969 | U32: 57.282 | V32: 57.333 | W32: 55.921 | X32: 55.942 | Y32: 55.327 | Z32: 55.326 | AA32: 53.978 | AB32: 53.969 | AC32: 54.047 | AD32: 51.077 | AE32: 48.944 | AF32: 50.336 | AG32: 50.605 | AH32: 47.63 | AI32: 46.095 | AJ32: 47.537 | AK32: 51.556 | AL32: 52.526 | AM32: 52.904 | AN32: 45.622 | AO32: 48.602 | AP32: 50.847 | AQ32: 53.682 | AR32: 53.488 | AS32: 56.289 | AT32: 54.028 | AU32: =IF(D32="","",INDEX([1]DICCIONARIO!$G$21:$H$33,MATCH('DATA NIQ'!D32,[1]DICCIONARIO!$G$21:$G$33,0),2)) -> 3D
A33: TOTAL ARGENTINA - ING | B33: GUARNICIONES PARA COPETIN | C33: PEPSICO | D33: 3D | E33: 3D | G33: Dist. Pond. Tiendas Handling | H33: =+A33&B33&C33&D33&E33&F33&G33 -> TOTAL ARGENTINA - INGGUARNICIONES PARA COPETINPEPSICO3D3DDist. Pond. Tiendas Handling | I33: 85.016 | J33: 84.848 | K33: 85.571 | L33: 85.855 | M33: 87.187 | N33: 85.965 | O33: 85.616 | P33: 86.63 | Q33: 85.934 | R33: 84.955 | S33: 84.885 | T33: 84.079 | U33: 81.726 | V33: 81.945 | W33: 83.082 | X33: 83.65 | Y33: 84.467 | Z33: 83.627 | AA33: 81.805 | AB33: 81.496 | AC33: 82.408 | AD33: 83.865 | AE33: 83.531 | AF33: 84.03 | AG33: 81.511 | AH33: 76.993 | AI33: 80.082 | AJ33: 81.21 | AK33: 83.115 | AL33: 83.242 | AM33: 81.974 | AN33: 68.65 | AO33: 78.946 | AP33: 82.697 | AQ33: 84.189 | AR33: 85.025 | AS33: 86.202 | AT33: 84.047 | AU33: =IF(D33="","",INDEX([1]DICCIONARIO!$G$21:$H$33,MATCH('DATA NIQ'!D33,[1]DICCIONARIO!$G$21:$G$33,0),2)) -> 3D
A34: TOTAL ARGENTINA - ING | B34: GUARNICIONES PARA COPETIN | C34: PEPSICO | D34: 3D | E34: 3D | G34: Part. de Vtas (KILOS) - Product | H34: =+A34&B34&C34&D34&E34&F34&G34 -> TOTAL ARGENTINA - INGGUARNICIONES PARA COPETINPEPSICO3D3DPart. de Vtas (KILOS) - Product | I34: 4.824 | J34: 4.744 | K34: 4.406 | L34: 4.441 | M34: 4.482 | N34: 4.347 | O34: 4.354 | P34: 3.945 | Q34: 4.313 | R34: 4.447 | S34: 4.35 | T34: 3.962 | U34: 3.729 | V34: 3.581 | W34: 3.855 | X34: 3.708 | Y34: 3.811 | Z34: 3.773 | AA34: 3.269 | AB34: 2.665 | AC34: 3.217 | AD34: 3.164 | AE34: 3.048 | AF34: 2.932 | AG34: 2.838 | AH34: 2.503 | AI34: 2.486 | AJ34: 2.711 | AK34: 3.073 | AL34: 2.996 | AM34: 2.548 | AN34: 1.464 | AO34: 2.043 | AP34: 2.817 | AQ34: 2.892 | AR34: 3.085 | AS34: 3.077 | AT34: 2.836 | AU34: =IF(D34="","",INDEX([1]DICCIONARIO!$G$21:$H$33,MATCH('DATA NIQ'!D34,[1]DICCIONARIO!$G$21:$G$33,0),2)) -> 3D
A35: TOTAL ARGENTINA - ING | B35: GUARNICIONES PARA COPETIN | C35: PEPSICO | D35: 3D | E35: 3D | G35: Part. de Vtas Valor - Product | H35: =+A35&B35&C35&D35&E35&F35&G35 -> TOTAL ARGENTINA - INGGUARNICIONES PARA COPETINPEPSICO3D3DPart. de Vtas Valor - Product | I35: 6.758 | J35: 6.778 | K35: 6.391 | L35: 6.338 | M35: 6.427 | N35: 6.331 | O35: 6.37 | P35: 6.077 | Q35: 6.644 | R35: 6.747 | S35: 6.585 | T35: 5.96 | U35: 5.767 | V35: 5.588 | W35: 5.858 | X35: 5.691 | Y35: 5.635 | Z35: 5.568 | AA35: 5.161 | AB35: 4.575 | AC35: 4.961 | AD35: 4.818 | AE35: 4.834 | AF35: 4.66 | AG35: 4.592 | AH35: 4.164 | AI35: 4.05 | AJ35: 4.34 | AK35: 4.724 | AL35: 4.65 | AM35: 3.955 | AN35: 2.413 | AO35: 3.264 | AP35: 4.192 | AQ35: 4.338 | AR35: 4.586 | AS35: 4.582 | AT35: 4.278 | AU35: =IF(D35="","",INDEX([1]DICCIONARIO!$G$21:$H$33,MATCH('DATA NIQ'!D35,[1]DICCIONARIO!$G$21:$G$33,0),2)) -> 3D
A36: TOTAL ARGENTINA - ING | B36: GUARNICIONES PARA COPETIN | C36: PEPSICO | D36: 3D | E36: 3D | F36: 121 A 200 | G36: Vtas (KILOS) | H36: =+A36&B36&C36&D36&E36&F36&G36 -> TOTAL ARGENTINA - INGGUARNICIONES PARA COPETINPEPSICO3D3D121 A 200Vtas (KILOS) | I36: 51899.182 | J36: 54213.768 | K36: 52925.825 | L36: 48238.52 | M36: 48602.133 | N36: 52784.221 | O36: 51456.611 | P36: 60340.152 | Q36: 59421.109 | R36: 52070.606 | S36: 46417.873 | T36: 34564.421 | U36: 33497.543 | V36: 31804.509 | W36: 38812.156 | X36: 35153.992 | Y36: 36704.101 | Z36: 39351.081 | AA36: 29572.557 | AB36: 23446.92 | AC36: 24482.691 | AD36: 22161.929 | AE36: 20881.087 | AF36: 20524.257 | AG36: 20051.966 | AH36: 15007.828 | AI36: 22227.515 | AJ36: 19306.411 | AK36: 22431.397 | AL36: 21121.641 | AM36: 20007.842 | AN36: 13855.044 | AO36: 20148.964 | AP36: 28613.052 | AQ36: 29018.949 | AR36: 31227.506 | AS36: 29244.934 | AT36: 26342.649 | AU36: =IF(D36="","",INDEX([1]DICCIONARIO!$G$21:$H$33,MATCH(D36,[1]DICCIONARIO!$G$21:$G$33,0),2)) -> 3D
A37: TOTAL ARGENTINA - ING | B37: GUARNICIONES PARA COPETIN | C37: PEPSICO | D37: 3D | E37: 3D | F37: 121 A 200 | G37: Compras (KILOS) | H37: =+A37&B37&C37&D37&E37&F37&G37 -> TOTAL ARGENTINA - INGGUARNICIONES PARA COPETINPEPSICO3D3D121 A 200Compras (KILOS) | I37: 44294.188 | J37: 48019.974 | K37: 47853.141 | L37: 40405.263 | M37: 41613.683 | N37: 53219.753 | O37: 45579.473 | P37: 59119.857 | Q37: 57462.752 | R37: 44414.814 | S37: 40195.793 | T37: 30181.516 | U37: 30614.065 | V37: 26934.004 | W37: 31301.785 | X37: 30203.419 | Y37: 27643.835 | Z37: 40146.269 | AA37: 24561.851 | AB37: 25265.831 | AC37: 26211.116 | AD37: 18774.417 | AE37: 21090.557 | AF37: 15563.944 | AG37: 16794.245 | AH37: 13258.258 | AI37: 17796.314 | AJ37: 15209.689 | AK37: 18476.827 | AL37: 17745.179 | AM37: 13894.014 | AN37: 10873.775 | AO37: 19562.366 | AP37: 19764.219 | AQ37: 21681.197 | AR37: 18533.937 | AS37: 20802.511 | AT37: 15599.296 | AU37: =IF(D37="","",INDEX([1]DICCIONARIO!$G$21:$H$33,MATCH(D37,[1]DICCIONARIO!$G$21:$G$33,0),2)) -> 3D
A38: TOTAL ARGENTINA - ING | B38: GUARNICIONES PARA COPETIN | C38: PEPSICO | D38: 3D | E38: 3D | F38: 121 A 200 | G38: Inventario (KILOS) | H38: =+A38&B38&C38&D38&E38&F38&G38 -> TOTAL ARGENTINA - INGGUARNICIONES PARA COPETINPEPSICO3D3D121 A 200Inventario (KILOS) | I38: 17327.531 | J38: 17502.713 | K38: 17235.344 | L38: 16500.727 | M38: 17603.031 | N38: 24342.266 | O38: 21734.683 | P38: 24344.914 | Q38: 24045.433 | R38: 19467.235 | S38: 17599.845 | T38: 16557.069 | U38: 16213.745 | V38: 14972.587 | W38: 13296.199 | X38: 15070.305 | Y38: 14576.324 | Z38: 17362.12 | AA38: 11715.172 | AB38: 12441.134 | AC38: 13315.042 | AD38: 11064.957 | AE38: 13002.102 | AF38: 9680.874 | AG38: 8228.566 | AH38: 7503.45 | AI38: 8495.55 | AJ38: 7740.617 | AK38: 8817.282 | AL38: 9956.917 | AM38: 8191.368 | AN38: 6169.836 | AO38: 8933.609 | AP38: 10426.496 | AQ38: 11803.444 | AR38: 9525.651 | AS38: 11042.092 | AT38: 9426.369 | AU38: =IF(D38="","",INDEX([1]DICCIONARIO!$G$21:$H$33,MATCH(D38,[1]DICCIONARIO!$G$21:$G$33,0),2)) -> 3D
A39: TOTAL ARGENTINA - ING | B39: GUARNICIONES PARA COPETIN | C39: PEPSICO | D39: 3D | E39: 3D | F39: 121 A 200 | G39: Vtas Valor | H39: =+A39&B39&C39&D39&E39&F39&G39 -> TOTAL ARGENTINA - INGGUARNICIONES PARA COPETINPEPSICO3D3D121 A 200Vtas Valor | I39: 1.1007585e+08 | J39: 1.2110567e+08 | K39: 1.2831631e+08 | L39: 1.2412284e+08 | M39: 1.2940715e+08 | N39: 1.5542982e+08 | O39: 1.7420199e+08 | P39: 2.2763743e+08 | Q39: 2.4431947e+08 | R39: 2.3389329e+08 | S39: 2.237579e+08 | T39: 1.7404996e+08 | U39: 1.847287e+08 | V39: 1.7900535e+08 | W39: 2.2559095e+08 | X39: 2.3093103e+08 | Y39: 2.7059256e+08 | Z39: 3.3571937e+08 | AA39: 3.0287263e+08 | AB39: 2.9419547e+08 | AC39: 3.7505537e+08 | AD39: 4.1393573e+08 | AE39: 4.4583479e+08 | AF39: 4.421681e+08 | AG39: 4.6734166e+08 | AH39: 3.7104139e+08 | AI39: 5.5614719e+08 | AJ39: 4.9020144e+08 | AK39: 5.7750911e+08 | AL39: 5.7503488e+08 | AM39: 5.5738532e+08 | AN39: 3.9373744e+08 | AO39: 5.7216513e+08 | AP39: 8.0168692e+08 | AQ39: 8.4984368e+08 | AR39: 8.9494113e+08 | AS39: 8.5501468e+08 | AT39: 7.7386532e+08 | AU39: =IF(D39="","",INDEX([1]DICCIONARIO!$G$21:$H$33,MATCH(D39,[1]DICCIONARIO!$G$21:$G$33,0),2)) -> 3D
A40: TOTAL ARGENTINA - ING | B40: GUARNICIONES PARA COPETIN | C40: PEPSICO | D40: 3D | E40: 3D | F40: 121 A 200 | G40: Dist. Num. Tiendas Handling (C) | H40: =+A40&B40&C40&D40&E40&F40&G40 -> TOTAL ARGENTINA - INGGUARNICIONES PARA COPETINPEPSICO3D3D121 A 200Dist. Num. Tiendas Handling (C) | I40: 19.142 | J40: 19.577 | K40: 19.289 | L40: 19.449 | M40: 19.379 | N40: 21.535 | O40: 21.609 | P40: 20.714 | Q40: 20.134 | R40: 20.1 | S40: 18.74 | T40: 17.373 | U40: 16.943 | V40: 17.015 | W40: 15.57 | X40: 15.173 | Y40: 17.236 | Z40: 17.561 | AA40: 16.012 | AB40: 14.704 | AC40: 14.395 | AD40: 14.831 | AE40: 13.449 | AF40: 13.032 | AG40: 13.385 | AH40: 11.724 | AI40: 11.811 | AJ40: 10.783 | AK40: 11.756 | AL40: 12.074 | AM40: 12.253 | AN40: 10.68 | AO40: 11.739 | AP40: 12.857 | AQ40: 14.41 | AR40: 14.198 | AS40: 14.051 | AT40: 13.967 | AU40: =IF(D40="","",INDEX([1]DICCIONARIO!$G$21:$H$33,MATCH('DATA NIQ'!D40,[1]DICCIONARIO!$G$21:$G$33,0),2)) -> 3D
...
